Workbook
Name bn: 1000000000
Name GVKey: "104604-02w"
Name ra.B.TE: [1]ResultsA!$B$328:$AC$328
Name SPSet: "current"

Sheet #주가
A1: Refresh | B1: Last Update : 2026-05-20 17:20:49
A2: 0 | G2: 기준일 | H2: 46161
A3: Time Series (Company) | G3: 할증률 | H3: 0.1
A4: Frequency | B4: D | C4: D | D4: 0 | G4: 종목코드 | H4: A441270
A5: Period(From) | B5: =B6-50000 -> 20210519 | C5: Korean | D5: 0
A6: Period(To) | B6: =TEXT(H2,"yyyymmdd") -> 20260519 | D6: 0 | G6: 기준가격 산정 | H6: =MAX(AVERAGE(H7:H9),H9)*(1+H3) -> 11282.096
G7: 과거 1개월(A) | H7: =SUMIFS(D:D,A:A,">="&H2-30)/(1000*SUMIFS(C:C,A:A,">="&H2-30)) -> 10657.947
A8: Code | B8: =H4 -> A441270 | C8: =B8 -> A441270 | D8: =B8 -> A441270 | E8: =B8 -> A441270 | G8: 과거 1주일(B) | H8: =SUMIFS(D:D,A:A,">="&H2-7)/(1000*SUMIFS(C:C,A:A,">="&H2-7)) -> 10214.05
A9: Name | B9: 파인엠텍 | C9: 파인엠텍 | D9: 파인엠텍 | E9: 파인엠텍 | G9: 최근일(C) | H9: =SUMIFS(D:D,A:A,">="&H2)/(1000*SUMIFS(C:C,A:A,">="&H2)) -> 9897.3571
A10: Item Code | B10: S100300 | C10: S100900 | D10: S101200 | E10: S102100
A11: Unit | B11: Local/Shares | C11: Shares thou | D11: Local | E11: Local
A12: Base Date
A14: D A T E | B14: 수정주가 | C14: 거래량 | D14: 거래대금 | E14: 시가총액
A15: 46161 | B15: 9900 | C15: 435 | D15: 4305350335 | E15: 413138998800
A16: 46160 | B16: 9760 | C16: 253 | D16: 2435792150 | E16: 407296629120
A17: 46157 | B17: 9940 | C17: 606 | D17: 6041963970 | E17: 414808247280
A18: 46156 | B18: 10500 | C18: 313 | D18: 3288119880 | E18: 437783556000
A19: 46155 | B19: 10650 | C19: 884 | D19: 9410515365 | E19: 444037606800
A20: 46154 | B20: 10090 | C20: 465 | D20: 4710990595 | E20: 420689150480
A21: 46153 | B21: 10400 | C21: 356 | D21: 3669973690 | E21: 433614188800
A22: 46150 | B22: 10510 | C22: 236 | D22: 2451367805 | E22: 438200492720
A23: 46149 | B23: 10350 | C23: 531 | D23: 5511906205 | E23: 431529505200
A24: 46148 | B24: 10780 | C24: 370 | D24: 3961866950 | E24: 449457784160
A25: 46146 | B25: 10940 | C25: 486 | D25: 5346734045 | E25: 456128771680
A26: 46142 | B26: 10380 | C26: 345 | D26: 3633829530 | E26: 432780315360
... A896: 44841 | B896: 11100 | C896: 5886 | D896: 62077175120 | E896: 324889363200
A897: 44840
A898: 44839
A899: 44838
A900: 44834
A901: 44833
A902: 44832
A903: 44831
A904: 44830
A905: 44827
A906: 44826
A907: 44825
A908: 44824
... A1239: 44334

Sheet #보고서
B2: A200470 | C2: 에이팩트 | D2: 최근결산 | E2: 202506 | F2: 발행금액(억원) | G2: 200
B4: #별도 | P4: #연결
B6: 재무상태표 | C6: =Model_별도!J3 -> 2020 | D6: =Model_별도!K3 -> 2021 | E6: =Model_별도!L3 -> 2022 | F6: =Model_별도!M3 -> 2023 | G6: =Model_별도!N3 -> 2024 | H6: =RIGHT(Model_별도!O3,5) -> 24.2Q | I6: =RIGHT(Model_별도!P3,5) -> 25.2Q | J6: =Model_별도!Q21 -> 2025E | K6: =Model_별도!R21 -> 2026E | L6: =Model_별도!S21 -> 2027E | M6: =Model_별도!T21 -> 0 | N6: =Model_별도!U21 -> 0 | P6: 재무상태표 | Q6: =Model_연결!J21 -> 2020 | R6: =Model_연결!K21 -> 2021 | S6: =Model_연결!L21 -> 2022 | T6: =Model_연결!M21 -> 2023 | U6: =Model_연결!N21 -> 2024 | V6: =H6 -> 24.2Q | W6: =I6 -> 25.2Q | X6: =Model_연결!Q21 -> 2025E | Y6: =Model_연결!R21 -> 2026E | Z6: =Model_연결!S21 -> 2027E | AA6: =Model_연결!T21 -> 0 | AB6: =Model_연결!U21 -> 0
B7: 유동자산 | C7: =Model_별도!J81 -> 211.51 | D7: =Model_별도!K81 -> 212.39 | E7: =Model_별도!L81 -> 377.54 | F7: =Model_별도!M81 -> 343.34 | G7: =Model_별도!N81 -> 264.7 | H7: =Model_별도!O81 -> 344.16 | I7: =Model_별도!P81 -> 561.75 | J7: =Model_별도!Q81 -> 319.68 | ... N7: =Model_별도!U81 -> 0 | P7: 유동자산 | Q7: =Model_연결!J81 -> 0 | R7: =Model_연결!K81 -> 0 | S7: =Model_연결!L81 -> 0 | T7: =Model_연결!M81 -> 0 | U7: =Model_연결!N81 -> 0 | V7: =Model_연결!O81 -> 0 | W7: =Model_연결!P81 -> 0 | X7: =Model_연결!Q81 -> #DIV/0! | ... AB7: =Model_연결!U81 -> 0
B8: 현금및금융상품 | C8: =Model_별도!J62+Model_별도!J63 -> 176.06 | D8: =Model_별도!K62+Model_별도!K63 -> 185.83 | E8: =Model_별도!L62+Model_별도!L63 -> 182.06 | F8: =Model_별도!M62+Model_별도!M63 -> 217.37 | G8: =Model_별도!N62+Model_별도!N63 -> 141.6 | H8: =Model_별도!O62+Model_별도!O63 -> 240.75 | I8: =Model_별도!P62+Model_별도!P63 -> 82.32 | J8: =Model_별도!Q62+Model_별도!Q63 -> 314.84 | ... N8: =Model_별도!U62+Model_별도!U63 -> 0 | P8: 현금및금융상품 | Q8: =Model_연결!J62+Model_연결!J63 -> 0 | R8: =Model_연결!K62+Model_연결!K63 -> 0 | S8: =Model_연결!L62+Model_연결!L63 -> 0 | T8: =Model_연결!M62+Model_연결!M63 -> 0 | U8: =Model_연결!N62+Model_연결!N63 -> 0 | V8: =Model_연결!O62+Model_연결!O63 -> 0 | W8: =Model_연결!P62+Model_연결!P63 -> 0 | X8: =Model_연결!Q62+Model_연결!Q63 -> #DIV/0! | ... AB8: =Model_연결!U62+Model_연결!U63 -> 0
B9: 매출채권 | C9: =Model_별도!J72 -> 13.13 | D9: =Model_별도!K72 -> 22.68 | E9: =Model_별도!L72 -> 93.09 | F9: =Model_별도!M72 -> 59.66 | G9: =Model_별도!N72 -> 72.95 | H9: =Model_별도!O72 -> 63.62 | I9: =Model_별도!P72 -> 76.79 | J9: =Model_별도!Q72 -> 0 | ... N9: =Model_별도!U72 -> 0 | P9: 매출채권 | Q9: =Model_연결!J71 -> 0 | R9: =Model_연결!K71 -> 0 | S9: =Model_연결!L71 -> 0 | T9: =Model_연결!M71 -> 0 | U9: =Model_연결!N71 -> 0 | V9: =Model_연결!O71 -> 0 | W9: =Model_연결!P71 -> 0 | X9: =Model_연결!Q71 -> #DIV/0! | ... AB9: =Model_연결!U71 -> 0
B10: 재고자산 | C10: =Model_별도!J76 -> 0 | D10: =Model_별도!K76 -> 0 | E10: =Model_별도!L76 -> 83.17 | F10: =Model_별도!M76 -> 48.8 | G10: =Model_별도!N76 -> 35.83 | H10: =Model_별도!O76 -> 29.91 | I10: =Model_별도!P76 -> 40.11 | J10: =Model_별도!Q76 -> 0 | ... N10: =Model_별도!U76 -> 0 | P10: 재고자산 | Q10: =Model_연결!J77 -> 0 | R10: =Model_연결!K77 -> 0 | S10: =Model_연결!L77 -> 0 | T10: =Model_연결!M77 -> 0 | U10: =Model_연결!N77 -> 0 | V10: =Model_연결!O77 -> 0 | W10: =Model_연결!P77 -> 0 | X10: =Model_연결!Q77 -> #DIV/0! | ... AB10: =Model_연결!U77 -> 0
B11: 기타유동자산 | C11: =C7-SUM(C8:C10) -> 22.32 | D11: =D7-SUM(D8:D10) -> 3.88 | E11: =E7-SUM(E8:E10) -> 19.22 | F11: =F7-SUM(F8:F10) -> 17.51 | G11: =G7-SUM(G8:G10) -> 14.32 | H11: =H7-SUM(H8:H10) -> 9.88 | I11: =I7-SUM(I8:I10) -> 362.53 | J11: =J7-SUM(J8:J10) -> 4.84 | ... N11: =N7-SUM(N8:N10) -> 0 | P11: 기타유동자산 | Q11: =Q7-SUM(Q8:Q10) -> 0 | R11: =R7-SUM(R8:R10) -> 0 | S11: =S7-SUM(S8:S10) -> 0 | T11: =T7-SUM(T8:T10) -> 0 | U11: =U7-SUM(U8:U10) -> 0 | V11: =V7-SUM(V8:V10) -> 0 | W11: =W7-SUM(W8:W10) -> 0 | X11: =X7-SUM(X8:X10) -> #DIV/0! | ... AB11: =AB7-SUM(AB8:AB10) -> 0
B12: 비유동자산 | C12: =Model_별도!J96 -> 1092.73 | D12: =Model_별도!K96 -> 948.22 | E12: =Model_별도!L96 -> 1763.92 | F12: =Model_별도!M96 -> 1751.71 | G12: =Model_별도!N96 -> 1360.18 | H12: =Model_별도!O96 -> 1646.52 | I12: =Model_별도!P96 -> 988.13 | J12: =Model_별도!Q96 -> 1254.04 | ... N12: =Model_별도!U96 -> 0 | P12: 비유동자산 | Q12: =Model_연결!J96 -> 0 | R12: =Model_연결!K96 -> 0 | S12: =Model_연결!L96 -> 0 | T12: =Model_연결!M96 -> 0 | U12: =Model_연결!N96 -> 0 | V12: =Model_연결!O96 -> 0 | W12: =Model_연결!P96 -> 0 | X12: =Model_연결!Q96 -> #DIV/0! | ... AB12: =Model_연결!U96 -> 0
B13: 비유동기타금융자산 | C13: =Model_별도!J90 -> 1.73 | D13: =Model_별도!K90 -> 4.18 | E13: =Model_별도!L90 -> 14.13 | F13: =Model_별도!M90 -> 10.95 | G13: =Model_별도!N90 -> 0.6 | H13: =Model_별도!O90 -> 3.08 | I13: =Model_별도!P90 -> 0.42 | J13: =Model_별도!Q90 -> 0.6 | ... N13: =Model_별도!U90 -> 0 | P13: 비유동기타금융자산 | Q13: =Model_연결!J90 -> 0 | R13: =Model_연결!K90 -> 0 | S13: =Model_연결!L90 -> 0 | T13: =Model_연결!M90 -> 0 | U13: =Model_연결!N90 -> 0 | V13: =Model_연결!O90 -> 0 | W13: =Model_연결!P90 -> 0 | X13: =Model_연결!Q90 -> 0 | ... AA13: =Model_연결!T90 -> 0
B14: 유형자산(투자부동산 포함) | C14: =Model_별도!J86+Model_별도!J84+Model_별도!J85+Model_별도!J82 -> 1044.27 | D14: =Model_별도!K86+Model_별도!K84+Model_별도!K85+Model_별도!K82 -> 888.59 | E14: =Model_별도!L86+Model_별도!L84+Model_별도!L85+Model_별도!L82 -> 1621.29 | F14: =Model_별도!M86+Model_별도!M84+Model_별도!M85+Model_별도!M82 -> 1566.17 | G14: =Model_별도!N86+Model_별도!N84+Model_별도!N85+Model_별도!N82 -> 1218.93 | H14: =Model_별도!O86+Model_별도!O84+Model_별도!O85+Model_별도!O82 -> 1504.01 | I14: =Model_별도!P86+Model_별도!P84+Model_별도!P85+Model_별도!P82 -> 860.81 | J14: =Model_별도!Q86+Model_별도!Q84+Model_별도!Q85+Model_별도!Q82 -> 1112.79 | ... N14: =Model_별도!U86+Model_별도!U84+Model_별도!U85+Model_별도!U82 -> 0 | P14: 유형자산(투자부동산 포함) | Q14: =Model_연결!J86+Model_연결!J84+Model_연결!J82+Model_연결!J85 -> 0 | R14: =Model_연결!K86+Model_연결!K84+Model_연결!K82+Model_연결!K85 -> 0 | S14: =Model_연결!L86+Model_연결!L84+Model_연결!L82+Model_연결!L85 -> 0 | T14: =Model_연결!M86+Model_연결!M84+Model_연결!M82+Model_연결!M85 -> 0 | U14: =Model_연결!N86+Model_연결!N84+Model_연결!N82+Model_연결!N85 -> 0 | V14: =Model_연결!O86+Model_연결!O84+Model_연결!O82+Model_연결!O85 -> 0 | W14: =Model_연결!P86+Model_연결!P84+Model_연결!P82+Model_연결!P85 -> 0 | X14: =Model_연결!Q86+Model_연결!Q84+Model_연결!Q82+Model_연결!Q85 -> #DIV/0! | ... AB14: =Model_연결!U86+Model_연결!U84+Model_연결!U82+Model_연결!U85 -> 0
B15: 무형자산 | C15: =Model_별도!J88 -> 2.19 | D15: =Model_별도!K88 -> 7.73 | E15: =Model_별도!L88 -> 28.39 | F15: =Model_별도!M88 -> 21.37 | G15: =Model_별도!N88 -> 15.74 | H15: =Model_별도!O88 -> 19.23 | I15: =Model_별도!P88 -> 10.58 | J15: =Model_별도!Q88 -> 15.74 | ... N15: =Model_별도!U88 -> 0 | P15: 무형자산 | Q15: =Model_연결!J88 -> 0 | R15: =Model_연결!K88 -> 0 | S15: =Model_연결!L88 -> 0 | T15: =Model_연결!M88 -> 0 | U15: =Model_연결!N88 -> 0 | V15: =Model_연결!O88 -> 0 | W15: =Model_연결!P88 -> 0 | X15: =Model_연결!Q88 -> 0 | ... AB15: =Model_연결!U88 -> 0
B16: 관계기업등지분 | C16: =Model_별도!J83 -> 0 | D16: =Model_별도!K83 -> 0 | E16: =Model_별도!L83 -> 0 | F16: =Model_별도!M83 -> 0 | G16: =Model_별도!N83 -> 0 | H16: =Model_별도!O83 -> 0 | I16: =Model_별도!P83 -> 0 | J16: =Model_별도!Q83 -> 0 | ... N16: =Model_별도!U83 -> 0 | P16: 관계기업등지분 | Q16: =Model_연결!J83 -> 0 | R16: =Model_연결!K83 -> 0 | S16: =Model_연결!L83 -> 0 | T16: =Model_연결!M83 -> 0 | U16: =Model_연결!N83 -> 0 | V16: =Model_연결!O83 -> 0 | W16: =Model_연결!P83 -> 0 | X16: =Model_연결!Q83 -> 0 | ... AB16: =Model_연결!U83 -> 0
B17: 기타비유동자산 | C17: =C12-SUM(C13:C16) -> 44.54 | D17: =D12-SUM(D13:D16) -> 47.72 | E17: =E12-SUM(E13:E16) -> 100.11 | F17: =F12-SUM(F13:F16) -> 153.22 | G17: =G12-SUM(G13:G16) -> 124.91 | H17: =H12-SUM(H13:H16) -> 120.2 | I17: =I12-SUM(I13:I16) -> 116.32 | J17: =J12-SUM(J13:J16) -> 124.91 | ... N17: =N12-SUM(N13:N16) -> 0 | P17: 기타비유동자산 | Q17: =Q12-SUM(Q13:Q16) -> 0 | R17: =R12-SUM(R13:R16) -> 0 | S17: =S12-SUM(S13:S16) -> 0 | T17: =T12-SUM(T13:T16) -> 0 | U17: =U12-SUM(U13:U16) -> 0 | V17: =V12-SUM(V13:V16) -> 0 | W17: =W12-SUM(W13:W16) -> 0 | X17: =X12-SUM(X13:X16) -> #DIV/0! | ... AB17: =AB12-SUM(AB13:AB16) -> 0
B18: 자산총계 | C18: =C12+C7 -> 1304.24 | D18: =D12+D7 -> 1160.61 | E18: =E12+E7 -> 2141.46 | F18: =F12+F7 -> 2095.05 | G18: =G12+G7 -> 1624.88 | H18: =H12+H7 -> 1990.68 | I18: =I12+I7 -> 1549.88 | J18: =J12+J7 -> 1573.72 | ... N18: =N12+N7 -> 0 | P18: 자산총계 | Q18: =Q12+Q7 -> 0 | R18: =R12+R7 -> 0 | S18: =S12+S7 -> 0 | T18: =T12+T7 -> 0 | U18: =U12+U7 -> 0 | V18: =V12+V7 -> 0 | W18: =W12+W7 -> 0 | X18: =X12+X7 -> #DIV/0! | ... AB18: =AB12+AB7 -> 0
B19: 유동부채 | C19: =Model_별도!J113 -> 389.9 | D19: =Model_별도!K113 -> 275.2 | E19: =Model_별도!L113 -> 427.44 | F19: =Model_별도!M113 -> 806.17 | G19: =Model_별도!N113 -> 863.12 | H19: =Model_별도!O113 -> 842.63 | I19: =Model_별도!P113 -> 824.85 | J19: =Model_별도!Q113 -> 811.74 | ... N19: =Model_별도!U113 -> 0 | P19: 유동부채 | Q19: =Model_연결!J113 -> 0 | R19: =Model_연결!K113 -> 0 | S19: =Model_연결!L113 -> 0 | T19: =Model_연결!M113 -> 0 | U19: =Model_연결!N113 -> 0 | V19: =Model_연결!O113 -> 0 | W19: =Model_연결!P113 -> 0 | X19: =Model_연결!Q113 -> #DIV/0! | ... AB19: =Model_연결!U113 -> 0
B20: 매입채무 | C20: =Model_별도!J98 -> 0 | D20: =Model_별도!K98 -> 0 | E20: =Model_별도!L98 -> 68.85 | F20: =Model_별도!M98 -> 26.63 | G20: =Model_별도!N98 -> 51.38 | H20: =Model_별도!O98 -> 25.51 | I20: =Model_별도!P98 -> 56.12 | J20: =Model_별도!Q98 -> 0 | ... N20: =Model_별도!U98 -> 0 | P20: 매입채무 | Q20: =Model_연결!J98 -> 0 | R20: =Model_연결!K98 -> 0 | S20: =Model_연결!L98 -> 0 | T20: =Model_연결!M98 -> 0 | U20: =Model_연결!N98 -> 0 | V20: =Model_연결!O98 -> 0 | W20: =Model_연결!P98 -> 0 | X20: =Model_연결!Q98 -> #DIV/0! | ... AB20: =Model_연결!U98 -> 0
B21: 단기차입금 | C21: =Model_별도!J105 -> 320.7 | D21: =Model_별도!K105 -> 238.75 | E21: =Model_별도!L105 -> 185 | F21: =Model_별도!M105 -> 665 | G21: =Model_별도!N105 -> 719 | H21: =Model_별도!O105 -> 725 | I21: =Model_별도!P105 -> 677 | J21: =Model_별도!Q105 -> 719 | ... N21: =Model_별도!U105 -> 0 | P21: 단기차입금 | Q21: =Model_연결!J105 -> 0 | R21: =Model_연결!K105 -> 0 | S21: =Model_연결!L105 -> 0 | T21: =Model_연결!M105 -> 0 | U21: =Model_연결!N105 -> 0 | V21: =Model_연결!O105 -> 0 | W21: =Model_연결!P105 -> 0 | X21: =Model_연결!Q105 -> 0 | ... AB21: =Model_연결!U105 -> 0
B22: 기타유동부채 | C22: =C19-SUM(C20:C21) -> 69.2 | D22: =D19-SUM(D20:D21) -> 36.45 | E22: =E19-SUM(E20:E21) -> 173.59 | F22: =F19-SUM(F20:F21) -> 114.54 | G22: =G19-SUM(G20:G21) -> 92.74 | H22: =H19-SUM(H20:H21) -> 92.12 | I22: =I19-SUM(I20:I21) -> 91.73 | J22: =J19-SUM(J20:J21) -> 92.74 | ... N22: =N19-SUM(N20:N21) -> 0 | P22: 기타유동부채 | Q22: =Q19-SUM(Q20:Q21) -> 0 | R22: =R19-SUM(R20:R21) -> 0 | S22: =S19-SUM(S20:S21) -> 0 | T22: =T19-SUM(T20:T21) -> 0 | U22: =U19-SUM(U20:U21) -> 0 | V22: =V19-SUM(V20:V21) -> 0 | W22: =W19-SUM(W20:W21) -> 0 | X22: =X19-SUM(X20:X21) -> #DIV/0! | ... AB22: =AB19-SUM(AB20:AB21) -> 0
B23: 비유동부채 | C23: =Model_별도!J122 -> 241.85 | D23: =Model_별도!K122 -> 176.49 | E23: =Model_별도!L122 -> 566.28 | F23: =Model_별도!M122 -> 308.08 | G23: =Model_별도!N122 -> 209.4 | H23: =Model_별도!O122 -> 255.62 | I23: =Model_별도!P122 -> 215.46 | J23: =Model_별도!Q122 -> 209.4 | ... N23: =Model_별도!U122 -> 0 | P23: 비유동부채 | Q23: =Model_연결!J122 -> 0 | R23: =Model_연결!K122 -> 0 | S23: =Model_연결!L122 -> 0 | T23: =Model_연결!M122 -> 0 | U23: =Model_연결!N122 -> 0 | V23: =Model_연결!O122 -> 0 | W23: =Model_연결!P122 -> 0 | X23: =Model_연결!Q122 -> 200 | ... AB23: =Model_연결!U122 -> 0
B24: 장기차입금 | C24: =Model_별도!J114 -> 231.25 | D24: =Model_별도!K114 -> 175 | E24: =Model_별도!L114 -> 550 | F24: =Model_별도!M114 -> 300 | G24: =Model_별도!N114 -> 200 | H24: =Model_별도!O114 -> 250 | I24: =Model_별도!P114 -> 195 | J24: =Model_별도!Q114 -> 200 | ... N24: =Model_별도!U114 -> 0 | P24: 장기차입금 | Q24: =Model_연결!J114 -> 0 | R24: =Model_연결!K114 -> 0 | S24: =Model_연결!L114 -> 0 | T24: =Model_연결!M114 -> 0 | U24: =Model_연결!N114 -> 0 | V24: =Model_연결!O114 -> 0 | W24: =Model_연결!P114 -> 0 | X24: =Model_연결!Q114 -> 200 | ... AB24: =Model_연결!U114 -> 0
B25: 기타비유동부채 | C25: =C23-C24 -> 10.6 | D25: =D23-D24 -> 1.49 | E25: =E23-E24 -> 16.28 | F25: =F23-F24 -> 8.08 | G25: =G23-G24 -> 9.4 | H25: =H23-H24 -> 5.62 | I25: =I23-I24 -> 20.46 | J25: =J23-J24 -> 9.4 | ... N25: =N23-N24 -> 0 | P25: 기타비유동부채 | Q25: =Q23-Q24 -> 0 | R25: =R23-R24 -> 0 | S25: =S23-S24 -> 0 | T25: =T23-T24 -> 0 | U25: =U23-U24 -> 0 | V25: =V23-V24 -> 0 | W25: =W23-W24 -> 0 | X25: =X23-X24 -> 0 | ... AB25: =AB23-AB24 -> 0
B26: 부채총계 | C26: =C23+C19 -> 631.75 | D26: =D23+D19 -> 451.69 | E26: =E23+E19 -> 993.72 | F26: =F23+F19 -> 1114.25 | G26: =G23+G19 -> 1072.52 | H26: =H23+H19 -> 1098.25 | I26: =I23+I19 -> 1040.31 | J26: =J23+J19 -> 1021.14 | ... N26: =N23+N19 -> 0 | P26: 부채총계 | Q26: =Q23+Q19 -> 0 | R26: =R23+R19 -> 0 | S26: =S23+S19 -> 0 | T26: =T23+T19 -> 0 | U26: =U23+U19 -> 0 | V26: =V23+V19 -> 0 | W26: =W23+W19 -> 0 | X26: =X23+X19 -> #DIV/0! | ... AB26: =AB23+AB19 -> 0
B27: 자본금 | C27: =Model_별도!J124 -> 87.77 | D27: =Model_별도!K124 -> 92.38 | E27: =Model_별도!L124 -> 211.81 | F27: =Model_별도!M124 -> 211.81 | G27: =Model_별도!N124 -> 211.81 | H27: =Model_별도!O124 -> 211.81 | I27: =Model_별도!P124 -> 211.81 | J27: =Model_별도!Q124 -> 211.81 | ... N27: =Model_별도!U124 -> 0 | P27: 자본금 | Q27: =Model_연결!J124 -> 0 | R27: =Model_연결!K124 -> 0 | S27: =Model_연결!L124 -> 0 | T27: =Model_연결!M124 -> 0 | U27: =Model_연결!N124 -> 0 | V27: =Model_연결!O124 -> 0 | W27: =Model_연결!P124 -> 0 | X27: =Model_연결!Q124 -> 0 | ... AB27: =Model_연결!U124 -> 0
B28: 기타자본 | C28: =C30-C29-C27 -> 211.78 | D28: =D30-D29-D27 -> 215.16 | E28: =E30-E29-E27 -> 502.28 | F28: =F30-F29-F27 -> 502.25 | G28: =G30-G29-G27 -> 588.3 | H28: =H30-H29-H27 -> 588.3 | I28: =I30-I29-I27 -> 588.3 | J28: =J30-J29-J27 -> 588.3 | ... N28: =N30-N29-N27 -> 0 | P28: 기타자본 | Q28: =Q30-Q29-Q27 -> 0 | R28: =R30-R29-R27 -> 0 | S28: =S30-S29-S27 -> 0 | T28: =T30-T29-T27 -> 0 | U28: =U30-U29-U27 -> 0 | V28: =V30-V29-V27 -> 0 | W28: =W30-W29-W27 -> 0 | X28: =X30-X29-X27 -> #DIV/0! | ... AB28: =AB30-AB29-AB27 -> 0
B29: 이익잉여금 | C29: =Model_별도!J128 -> 372.94 | D29: =Model_별도!K128 -> 401.38 | E29: =Model_별도!L128 -> 433.64 | F29: =Model_별도!M128 -> 266.75 | G29: =Model_별도!N128 -> -247.75 | H29: =Model_별도!O128 -> 92.33 | I29: =Model_별도!P128 -> -290.54 | J29: =Model_별도!Q128 -> -247.53 | ... N29: =Model_별도!U128 -> 0 | P29: 이익잉여금 | Q29: =Model_연결!J128 -> 0 | R29: =Model_연결!K128 -> 0 | S29: =Model_연결!L128 -> 0 | T29: =Model_연결!M128 -> 0 | U29: =Model_연결!N128 -> 0 | V29: =Model_연결!O128 -> 0 | W29: =Model_연결!P128 -> 0 | X29: =Model_연결!Q128 -> #DIV/0! | ... AB29: =Model_연결!U128 -> 0
B30: 자본총계 | C30: =Model_별도!J131 -> 672.49 | D30: =Model_별도!K131 -> 708.92 | E30: =Model_별도!L131 -> 1147.73 | F30: =Model_별도!M131 -> 980.81 | G30: =Model_별도!N131 -> 552.36 | H30: =Model_별도!O131 -> 892.44 | I30: =Model_별도!P131 -> 509.57 | J30: =Model_별도!Q131 -> 552.58 | ... N30: =Model_별도!U131 -> 0 | P30: 자본총계 | Q30: =Model_연결!J131 -> 0 | R30: =Model_연결!K131 -> 0 | S30: =Model_연결!L131 -> 0 | T30: =Model_연결!M131 -> 0 | U30: =Model_연결!N131 -> 0 | V30: =Model_연결!O131 -> 0 | W30: =Model_연결!P131 -> 0 | X30: =Model_연결!Q131 -> #DIV/0! | ... AB30: =Model_연결!U131 -> 0
B31: 총차입금 | C31: =Model_별도!J13 -> 551.95 | D31: =Model_별도!K13 -> 413.75 | E31: =Model_별도!L13 -> 735 | F31: =Model_별도!M13 -> 965 | G31: =Model_별도!N13 -> 919 | H31: =Model_별도!O13 -> 975 | I31: =Model_별도!P13 -> 872 | J31: =Model_별도!Q13 -> 919 | ... N31: =Model_별도!U13 -> 0 | P31: 총차입금 | Q31: =Model_연결!J13 -> 0 | R31: =Model_연결!K13 -> 0 | S31: =Model_연결!L13 -> 0 | T31: =Model_연결!M13 -> 0 | U31: =Model_연결!N13 -> 0 | V31: =Model_연결!O13 -> 0 | W31: =Model_연결!P13 -> 0 | X31: =Model_연결!Q13 -> 200 | ... AB31: =Model_연결!U13 -> 0
B32: 현금 및 장단기금융자산 | C32: =C31-C33 -> 177.79 | D32: =D31-D33 -> 190.01 | E32: =E31-E33 -> 196.19 | F32: =F31-F33 -> 228.32 | G32: =G31-G33 -> 142.2 | H32: =H31-H33 -> 243.83 | I32: =I31-I33 -> 82.74 | J32: =J31-J33 -> 315.44 | ... N32: =N31-N33 -> 0 | P32: 현금 및 예금 | Q32: =Q31-Q33 -> 0 | R32: =R31-R33 -> 0 | S32: =S31-S33 -> 0 | T32: =T31-T33 -> 0 | U32: =U31-U33 -> 0 | V32: =V31-V33 -> 0 | W32: =W31-W33 -> 0 | X32: =X31-X33 -> #DIV/0! | ... AB32: =AB31-AB33 -> 0
B33: 순차입금 | C33: =Model_별도!J14 -> 374.16 | D33: =Model_별도!K14 -> 223.74 | E33: =Model_별도!L14 -> 538.81 | F33: =Model_별도!M14 -> 736.68 | G33: =Model_별도!N14 -> 776.8 | H33: =Model_별도!O14 -> 731.17 | I33: =Model_별도!P14 -> 789.26 | J33: =Model_별도!Q14 -> 603.56 | ... N33: =Model_별도!U14 -> 0 | P33: 순차입금 | Q33: =Model_연결!J14 -> 0 | R33: =Model_연결!K14 -> 0 | S33: =Model_연결!L14 -> 0 | T33: =Model_연결!M14 -> 0 | U33: =Model_연결!N14 -> 0 | V33: =Model_연결!O14 -> 0 | W33: =Model_연결!P14 -> 0 | X33: =Model_연결!Q14 -> #DIV/0! | ... AB33: =Model_연결!U14 -> 0
B34: 순차입금/EBITDA | C34: =Model_별도!J17 -> 1.8443338 | D34: =Model_별도!K17 -> 1.2649254 | E34: =Model_별도!L17 -> 2.8395784 | F34: =Model_별도!M17 -> -105.08987 | G34: =Model_별도!N17 -> 197.15736 | H34: =Model_별도!O17 -> -20.890571 | I34: =Model_별도!P17 -> 8.9464974 | J34: =Model_별도!Q17 -> 5.1843326 | ... N34: =Model_별도!U17 -> 0 | P34: 순차입금/EBITDA | Q34: =Model_연결!J17 -> #DIV/0! | R34: =Model_연결!K17 -> #DIV/0! | S34: =Model_연결!L17 -> #DIV/0! | T34: =Model_연결!M17 -> #DIV/0! | U34: =Model_연결!N17 -> #DIV/0! | V34: =Model_연결!O17 -> #DIV/0! | W34: =Model_연결!P17 -> #DIV/0! | X34: =Model_연결!Q17 -> #DIV/0! | ... AB34: =Model_연결!U17 -> 0
B35: 단기차입비중 | C35: =C21/C31 -> 0.58103089 | D35: =D21/D31 -> 0.57703927 | E35: =E21/E31 -> 0.25170068 | F35: =F21/F31 -> 0.68911917 | G35: =G21/G31 -> 0.78237214 | H35: =H21/H31 -> 0.74358974 | I35: =I21/I31 -> 0.77637615 | J35: =J21/J31 -> 0.78237214 | ... N35: =N21/N31 -> #DIV/0! | P35: 단기차입비중 | Q35: =Q21/Q31 -> #DIV/0! | R35: =R21/R31 -> #DIV/0! | S35: =S21/S31 -> #DIV/0! | T35: =T21/T31 -> #DIV/0! | U35: =U21/U31 -> #DIV/0! | V35: =V21/V31 -> #DIV/0! | W35: =W21/W31 -> #DIV/0! | X35: =X21/X31 -> 0 | ... AB35: =AB21/AB31 -> #DIV/0!
B36: 부채비율 | C36: =Model_별도!J18 -> 0.93941917 | D36: =Model_별도!K18 -> 0.63715229 | E36: =Model_별도!L18 -> 0.86581339 | F36: =Model_별도!M18 -> 1.1360508 | G36: =Model_별도!N18 -> 1.9417047 | H36: =Model_별도!O18 -> 1.2306149 | I36: =Model_별도!P18 -> 2.0415448 | J36: =Model_별도!Q18 -> 1.8479496 | ... N36: =Model_별도!U18 -> 0 | P36: 부채비율 | Q36: =Model_연결!J18 -> #DIV/0! | R36: =Model_연결!K18 -> #DIV/0! | S36: =Model_연결!L18 -> #DIV/0! | T36: =Model_연결!M18 -> #DIV/0! | U36: =Model_연결!N18 -> #DIV/0! | V36: =Model_연결!O18 -> #DIV/0! | W36: =Model_연결!P18 -> #DIV/0! | X36: =Model_연결!Q18 -> #DIV/0! | ... AB36: =Model_연결!U18 -> 0
B37: 차입금의존도 | C37: =Model_별도!J19 -> 0.42319665 | D37: =Model_별도!K19 -> 0.35649357 | E37: =Model_별도!L19 -> 0.34322378 | F37: =Model_별도!M19 -> 0.46060953 | G37: =Model_별도!N19 -> 0.56558023 | H37: =Model_별도!O19 -> 0.48978239 | I37: =Model_별도!P19 -> 0.5626242 | J37: =Model_별도!Q19 -> 0.58396665 | ... N37: =Model_별도!U19 -> 0 | P37: 차입금의존도 | Q37: =Model_연결!J19 -> #DIV/0! | R37: =Model_연결!K19 -> #DIV/0! | S37: =Model_연결!L19 -> #DIV/0! | T37: =Model_연결!M19 -> #DIV/0! | U37: =Model_연결!N19 -> #DIV/0! | V37: =Model_연결!O19 -> #DIV/0! | W37: =Model_연결!P19 -> #DIV/0! | X37: =Model_연결!Q19 -> #DIV/0! | ... AB37: =Model_연결!U19 -> 0
B39: 손익계산서 | C39: =C6 -> 2020 | D39: =D6 -> 2021 | E39: =E6 -> 2022 | F39: =F6 -> 2023 | G39: =G6 -> 2024 | H39: =V6 -> 24.2Q | I39: =W6 -> 25.2Q | J39: =J6 -> 2025E | K39: =K6 -> 2026E | L39: =L6 -> 2027E | M39: =M6 -> 0 | N39: =N6 -> 0 | P39: 손익계산서 | Q39: =Q6 -> 2020 | R39: =R6 -> 2021 | S39: =S6 -> 2022 | T39: =T6 -> 2023 | U39: =U6 -> 2024 | V39: =V6 -> 24.2Q | W39: =W6 -> 25.2Q | X39: =X6 -> 2025E | ... AB39: =AB6 -> 0
B40: 매출액 | C40: =Model_별도!J22 -> 496.3 | D40: =Model_별도!K22 -> 472.17 | E40: =Model_별도!L22 -> 736.46 | F40: =Model_별도!M22 -> 937.42 | G40: =Model_별도!N22 -> 867.23 | H40: =Model_별도!O22 -> 419.17 | I40: =Model_별도!P22 -> 500.61 | J40: =Model_별도!Q22 -> 0 | ... N40: =Model_별도!U22 -> 0 | P40: 매출액 | Q40: =Model_연결!J22 -> 0 | R40: =Model_연결!K22 -> 0 | S40: =Model_연결!L22 -> 0 | T40: =Model_연결!M22 -> 0 | U40: =Model_연결!N22 -> 0 | V40: =Model_연결!O22 -> 0 | W40: =Model_연결!P22 -> 0 | X40: =Model_연결!Q22 -> 1051 | ... AB40: =Model_연결!U22 -> 0
B41: 매출액증감률 | C41: =Model_별도!J23 -> 0.059541854 | D41: =Model_별도!K23 -> -0.048619786 | E41: =Model_별도!L23 -> 0.55973484 | F41: =Model_별도!M23 -> 0.27287293 | G41: =Model_별도!N23 -> -0.074875723 | H41: - | I41: =Model_별도!P23 -> 0.19428871 | J41: =Model_별도!Q23 -> -1 | K41: =Model_별도!R23 -> #DIV/0! | L41: =Model_별도!S23 -> #DIV/0! | M41: =Model_별도!T23 -> 0 | N41: =Model_별도!U23 -> 0 | P41: 매출액증감률 | Q41: =Model_연결!J23 -> #DIV/0! | R41: =Model_연결!K23 -> #DIV/0! | S41: =Model_연결!L23 -> #DIV/0! | T41: =Model_연결!M23 -> #DIV/0! | U41: =Model_연결!N23 -> #DIV/0! | V41: - | W41: =Model_연결!P23 -> #DIV/0! | X41: =Model_연결!Q23 -> #DIV/0! | Y41: =Model_연결!R23 -> -1 | Z41: =Model_연결!S23 -> #DIV/0! | AA41: =Model_연결!T23 -> 0 | AB41: =Model_연결!U23 -> 0
B42: 매출원가 | C42: =Model_별도!J24 -> 396.91 | D42: =Model_별도!K24 -> 399.21 | E42: =Model_별도!L24 -> 649.72 | F42: =Model_별도!M24 -> 1098.7 | G42: =Model_별도!N24 -> 1022.3 | H42: =Model_별도!O24 -> 520.12 | I42: =Model_별도!P24 -> 489.32 | J42: =Model_별도!Q24 -> 0 | ... N42: =Model_별도!U24 -> 0 | P42: 매출원가 | Q42: =Model_연결!J24 -> 0 | R42: =Model_연결!K24 -> 0 | S42: =Model_연결!L24 -> 0 | T42: =Model_연결!M24 -> 0 | U42: =Model_연결!N24 -> 0 | V42: =Model_연결!O24 -> 0 | W42: =Model_연결!P24 -> 0 | X42: =Model_연결!Q24 -> #DIV/0! | ... AB42: =Model_연결!U24 -> 0
B43: 매출총이익 | C43: =C40-C42 -> 99.39 | D43: =D40-D42 -> 72.96 | E43: =E40-E42 -> 86.74 | F43: =F40-F42 -> -161.28 | G43: =G40-G42 -> -155.07 | H43: =H40-H42 -> -100.95 | I43: =I40-I42 -> 11.29 | J43: =J40-J42 -> 0 | ... N43: =N40-N42 -> 0 | P43: 매출총이익 | Q43: =Q40-Q42 -> 0 | R43: =R40-R42 -> 0 | S43: =S40-S42 -> 0 | T43: =T40-T42 -> 0 | U43: =U40-U42 -> 0 | V43: =V40-V42 -> 0 | W43: =W40-W42 -> 0 | X43: =X40-X42 -> #DIV/0! | ... AB43: =AB40-AB42 -> 0
B44: 매출총이익률 | C44: =C43/C$40 -> 0.20026194 | D44: =D43/D$40 -> 0.15452062 | E44: =E43/E$40 -> 0.11777965 | F44: =F43/F$40 -> -0.17204668 | G44: =G43/G$40 -> -0.1788107 | H44: =H43/H$40 -> -0.24083307 | I44: =I43/I$40 -> 0.022552486 | J44: =J43/J$40 -> #DIV/0! | ... N44: =N43/N$40 -> #DIV/0! | P44: 매출총이익률 | Q44: =Q43/Q$40 -> #DIV/0! | R44: =R43/R$40 -> #DIV/0! | S44: =S43/S$40 -> #DIV/0! | T44: =T43/T$40 -> #DIV/0! | U44: =U43/U$40 -> #DIV/0! | V44: =V43/V$40 -> #DIV/0! | W44: =W43/W$40 -> #DIV/0! | X44: =X43/X$40 -> #DIV/0! | ... AB44: =AB43/AB$40 -> #DIV/0!
...

Sheet 총괄장표
B2: 1. 재무지표 | C2: 연결
G4: AAA | H4: AA | I4: A | J4: BBB | K4: BB | L4: BB↓
D5: 수치 | E5: 비중 | F5: 점수 | G5: 10 | H5: 9 | I5: 8 | J5: 7 | K5: 5 | L5: 3
B6: 규모 | C6: 매출액(3년 평균) | D6: =IF($C$2="연결",AVERAGE(Model_연결!L4:N4),AVERAGE(Model_별도!L4:N4)) -> 0 | E6: 0.15 | F6: =IF(D6>=15000,$G$5,IF(D6>=10000,$H$5,IF(D6>=5000,$I$5,IF(D6>=1000,$J$5,IF(D6>=500,$K$5,$L$5))))) -> 3 | G6: ≥15000 | H6: ≥10000 | I6: ≥5000 | J6: ≥1000 | K6: ≥500 | L6: <500
B7: 수익성지표 | C7: 영업이익률(3년 평균) | D7: =IF($C$2="연결",SUM(Model_연결!L6:N6)/SUM(Model_연결!L4:N4),SUM(Model_별도!L6:N6)/SUM(Model_별도!L4:N4)) -> #DIV/0! | E7: 0.15 | F7: =IF(D7>=0.12,$G$5,IF(D7>=0.08,$H$5,IF(D7>=0.05,$I$5,IF(D7>=0.03,$J$5,IF(D7>=0,$K$5,$L$5))))) -> #DIV/0! | G7: ≥12% | H7: ≥8% | I7: ≥5% | J7: ≥3% | K7: ≥0% | L7: <0%
C8: EBITDA마진율(3년 평균) | D8: =IF($C$2="연결",SUM(Model_연결!L9:N9)/SUM(Model_연결!L4:N4),SUM(Model_별도!L9:N9)/SUM(Model_별도!L4:N4)) -> #DIV/0! | E8: 0.15 | F8: =IF(D8>=0.2,$G$5,IF(D8>=0.15,$H$5,IF(D8>=0.08,$I$5,IF(D8>=0.06,$J$5,IF(D8>=0.02,$K$5,$L$5))))) -> #DIV/0! | G8: ≥20% | H8: ≥15% | I8: ≥8% | J8: ≥6% | K8: ≥2% | L8: <2%
B9: 안정성지표 | C9: 자본금(최신) | D9: =IF($C$2="연결",Model_연결!P131,Model_별도!P131) -> 0 | E9: 0.05 | F9: =IF(D9>=5000,$G$5,IF(D9>=3000,$H$5,IF(D9>=2000,$I$5,IF(D9>=1000,$J$5,IF(D9>=400,$K$5,$L$5))))) -> 3 | G9: ≥5000 | H9: ≥3000 | I9: ≥2000 | J9: ≥1000 | K9: ≥400 | L9: <400
C10: 부채비율(최신) | D10: =IF($C$2="연결",Model_연결!P18,Model_별도!P18) -> #DIV/0! | E10: 0.1 | F10: =IF(D10<0.4,$G$5,IF(D10<1,$H$5,IF(D10<1.4,$I$5,IF(D10<1.8,$J$5,IF(D10<2.5,$K$5,$L$5))))) -> #DIV/0! | G10: <40% | H10: <100% | I10: <140% | J10: <180% | K10: <250% | L10: ≥250%
C11: 총차입금의존도(최신) | D11: =IF($C$2="연결",Model_연결!P12/Model_연결!P11,Model_별도!P12/Model_별도!P11) -> #DIV/0! | E11: 0.1 | F11: =IF(D11<0.1,$G$5,IF(D11<0.2,$H$5,IF(D11<0.3,$I$5,IF(D11<0.4,$J$5,IF(D11<0.5,$K$5,$L$5))))) -> #DIV/0! | G11: <10% | H11: <20% | I11: <30% | J11: <40% | K11: <50% | L11: ≥50%
C12: 운전자산 회전기일(매출액, 3년 평균) | D12: =IF($C$2="연결",AVERAGE(Model_연결!L72:N72)+AVERAGE(Model_연결!L78:N78),AVERAGE(Model_별도!L72:N72)+AVERAGE(Model_별도!L78:N78)) -> #DIV/0! | E12: 0.1 | F12: =IF(D12<80,$G$5,IF(D12<120,$H$5,IF(D12<150,$I$5,IF(D12<180,$J$5,IF(D12<200,$K$5,$L$5))))) -> #DIV/0! | G12: <80 | H12: <120 | I12: <150 | J12: <180 | K12: <200 | L12: ≥200
C13: EBITDA/이자비용(3년 평균) | D13: =IF($C$2="연결",SUM(Model_연결!L9:N9)/SUM(Model_연결!L40:N40),SUM(Model_별도!L9:N9)/SUM(Model_별도!L40:N40)) -> #DIV/0! | E13: 0.1 | F13: =IF(D13>=10,$G$5,IF(D13>=8,$H$5,IF(D13>=6,$I$5,IF(D13>=4,$J$5,IF(D13>=2,$K$5,$L$5))))) -> #DIV/0! | G13: ≥10 | H13: ≥8 | I13: ≥6 | J13: ≥4 | K13: ≥2 | L13: <2
C14: 순차입금(최신)/EBITDA(3년 평균) | D14: =IF($C$2="연결",IF(AVERAGE(Model_연결!L9:N9)<0,"음(-)의 EBITDA",Model_연결!P14/AVERAGE(Model_연결!L9:N9)),IF(AVERAGE(Model_연결!L9:N9)<0,"음(-)의 EBITDA",Model_별도!P14/AVERAGE(Model_별도!L9:N9))) -> #DIV/0! | E14: 0.1 | F14: =IF(D14<0.5,$G$5,IF(D14<2,$H$5,IF(D14<4,$I$5,IF(D14<6,$J$5,IF(D14<8,$K$5,$L$5))))) -> #DIV/0! | G14: <0.5 | H14: <2 | I14: <4 | J14: <6 | K14: <8 | L14: ≥8
E15: =SUM(E6:E14) -> 1 | F15: =SUMPRODUCT(E6:E14,F6:F14) -> #DIV/0!
B16: 2. 시가총액 | D16: =PEER!E14 -> 2111.75
B18: 3. 최근 2개연도 영업손익 | D18: '23년 | E18: '24년
D19: =IF($C$2="연결",Model_연결!M6,Model_별도!M6) -> 0 | E19: =IF($C$2="연결",Model_연결!N6,Model_별도!N6) -> 0
B21: 4. 금회차 포함 주식연계채권 발행 규모와 비율 | D21: 200 | E21: =D21/D16 -> 0.09470818
B23: 5. 대주주 리스크 | D23: 강승모 대표가 최대주주로 지분율 33.3% (특관자 계 49.5%로 지배구조 안정적). 3년내 대주주 변경 없음
C25: 주가 | F25: =주가!D15 -> 4985
C26: 120일 일평균 거래대금(억원) | F26: =PEER!CZ14/100000000 -> 15.949113
C27: 1년 중 최고 주가 | F27: =PEER!CX14 -> 1710
C28: 1년 중 최저 주가 | F28: =PEER!CY14 -> 5820

Sheet Model_별도
B1: =B3&" Financial Statements" -> 별도 Financial Statements
B2: (억원, except per share data) | D2: 18 | E2: =D2+1 -> 19 | F2: =E2+1 -> 20 | G2: =F2+1 -> 21 | H2: =G2+1 -> 22 | I2: =H2+1 -> 23 | J2: =I2+1 -> 24 | K2: =J2+1 -> 25 | L2: =K2+1 -> 26 | ... N2: =M2+1 -> 28 | O2: 65 | P2: =O2+4 -> 69 | Q2: 지우지마시오 (Vlookup 열순서)
B3: 별도 | C3: 과목코드 | D3: 2014 | E3: =D3+1 -> 2015 | F3: =E3+1 -> 2016 | G3: =F3+1 -> 2017 | H3: =G3+1 -> 2018 | I3: =H3+1 -> 2019 | J3: =I3+1 -> 2020 | K3: =J3+1 -> 2021 | L3: =K3+1 -> 2022 | ... N3: =M3+1 -> 2024 | O3: 2024.2Q | P3: 2025.2Q | Q3: 2025E | R3: 2026E | S3: 2027E | T3: 2028E
B4: 매출액 | D4: =D22 -> 315.19 | E4: =E22 -> 216.49 | F4: =F22 -> 158.78 | G4: =G22 -> 226.43 | H4: =H22 -> 471.15 | I4: =I22 -> 468.41 | J4: =J22 -> 496.3 | K4: =K22 -> 472.17 | ... S4: =S22 -> 0
B5: 매출성장률 | E5: =E4/D4-1 -> -0.31314445 | F5: =F4/E4-1 -> -0.2665712 | G5: =G4/F4-1 -> 0.42606122 | H5: =H4/G4-1 -> 1.0807755 | I5: =I4/H4-1 -> -0.0058155577 | J5: =J4/I4-1 -> 0.059541854 | K5: =K4/J4-1 -> -0.048619786 | L5: =L4/K4-1 -> 0.55973484 | ... N5: =N4/M4-1 -> -0.074875723 | P5: =P4/O4-1 -> 0.19428871 | Q5: =Q4/N4-1 -> -1 | R5: =R4/Q4-1 -> #DIV/0! | S5: =S4/R4-1 -> #DIV/0!
B6: 영업이익 | D6: =D32 -> 23.15 | E6: =E32 -> -41.64 | F6: =F32 -> -34.39 | G6: =G32 -> 19.47 | H6: =H32 -> 159.82 | I6: =I32 -> 81.68 | J6: =J32 -> 65.45 | K6: =K32 -> 40.2 | ... S6: =S32 -> 0
B7: 영업이익률 | D7: =D6/D4 -> 0.073447762 | E7: =E6/E4 -> -0.19234145 | F7: =F6/F4 -> -0.21658899 | G7: =G6/G4 -> 0.085986839 | H7: =H6/H4 -> 0.33921257 | I7: =I6/I4 -> 0.17437715 | J7: =J6/J4 -> 0.13187588 | K7: =K6/K4 -> 0.085138827 | ... S7: =S6/S4 -> #DIV/0!
B8: 당기순이익 | D8: =D52 -> 29.61 | E8: =E52 -> -21.29 | F8: =F52 -> -36.84 | G8: =G52 -> 8.63 | H8: =H52 -> 148.18 | I8: =I52 -> 41.89 | J8: =J52 -> 66.6 | K8: =K52 -> 26.65 | ... S8: =S52 -> 0.22
B9: EBITDA | D9: =D250 -> 164.22 | E9: =E250 -> 63.16 | F9: =F250 -> 41.57 | G9: =G250 -> 87.18 | H9: =H250 -> 284.7 | I9: =I250 -> 221.91 | J9: =J250 -> 202.87 | K9: =K250 -> 176.88 | ... S9: =S250 -> 71.712538
B10: EBITDA/매출액 | D10: =D9/D4 -> 0.52101907 | E10: =E9/E4 -> 0.29174558 | F10: =F9/F4 -> 0.26180879 | G10: =G9/G4 -> 0.38501965 | H10: =H9/H4 -> 0.60426616 | I10: =I9/I4 -> 0.47375163 | J10: =J9/J4 -> 0.40876486 | K10: =K9/K4 -> 0.37461084 | ... S10: =S9/S4 -> #DIV/0!
B11: 자산총계 | D11: =D97 -> 638.62 | E11: =E97 -> 571.5 | F11: =F97 -> 494.14 | G11: =G97 -> 688.91 | H11: =H97 -> 1231.62 | I11: =I97 -> 1274.09 | J11: =J97 -> 1304.24 | K11: =K97 -> 1160.61 | ... S11: =S97 -> 1574.16
B12: 부동산(토지+건물) | D12: =D82+D84+D85 -> 179.17 | E12: =E82+E84+E85 -> 174.77 | F12: =F82+F84+F85 -> 170.37 | G12: =G82+G84+G85 -> 165.97 | H12: =H82+H84+H85 -> 191.11 | I12: =I82+I84+I85 -> 460.91 | J12: =J82+J84+J85 -> 447.86 | K12: =K82+K84+K85 -> 425.41 | ... S12: =S82+S84+S85 -> 665.73
B13: 총차입금 | D13: =D105+D114 -> 158 | E13: =E105+E114 -> 118.25 | F13: =F105+F114 -> 78.5 | G13: =G105+G114 -> 238.75 | H13: =H105+H114 -> 540.45 | I13: =I105+I114 -> 598.55 | J13: =J105+J114 -> 551.95 | K13: =K105+K114 -> 413.75 | ... S13: =S105+S114 -> 919
B14: 순차입금 | D14: =D105+D114-D62-D63-D90 -> -13.47 | E14: =E105+E114-E62-E63-E90 -> -64.05 | F14: =F105+F114-F62-F63-F90 -> -120.9 | G14: =G105+G114-G62-G63-G90 -> 24.78 | H14: =H105+H114-H62-H63-H90 -> 198.91 | I14: =I105+I114-I62-I63-I90 -> 447.22 | J14: =J105+J114-J62-J63-J90 -> 374.16 | K14: =K105+K114-K62-K63-K90 -> 223.74 | ... S14: =S105+S114-S62-S63-S90 -> 466.66796
B15: OCF | D15: =D169 -> 157.94 | E15: =E169 -> 53.7 | F15: =F169 -> 47.49 | G15: =G169 -> 71.17 | H15: =H169 -> 289.72 | I15: =I169 -> 160.69 | J15: =J169 -> 206.06 | K15: =K169 -> 139.38 | ... S15: =S169 -> 71.932538
B16: 유무형자산투자 | D16: =D170+D171 -> -20.59 | E16: =E170+E171 -> -31.16 | F16: =F170+F171 -> -2.02 | G16: =G170+G171 -> -228.33 | H16: =H170+H171 -> -496.7 | I16: =I170+I171 -> -396.35 | J16: =J170+J171 -> -120.53 | K16: =K170+K171 -> -10.93 | ... S16: =S170+S171 -> -10.28
B17: 순차입금/EBITDA | D17: =D14/D9 -> -0.082024114 | E17: =E14/E9 -> -1.0140912 | F17: =F14/F9 -> -2.9083474 | G17: =G14/G9 -> 0.2842395 | H17: =H14/H9 -> 0.69866526 | I17: =I14/I9 -> 2.0153215 | J17: =J14/J9 -> 1.8443338 | K17: =K14/K9 -> 1.2649254 | ... N17: =N14/N9 -> 197.15736 | O17: =O14/(O9*IF(RIGHT(O$3,2)="1Q",4,IF(RIGHT(O$3,2)="2Q",2,IF(RIGHT(O$3,2)="3Q",4/3,"0")))) -> -20.890571 | P17: =P14/(P9*IF(RIGHT(P$3,2)="1Q",4,IF(RIGHT(P$3,2)="2Q",2,IF(RIGHT(P$3,2)="3Q",4/3,"0")))) -> 8.9464974 | Q17: =Q14/Q9 -> 5.1843326 | R17: =R14/R9 -> 6.1937116 | S17: =S14/S9 -> 6.5074808
B18: 부채비율 | D18: =D123/D131 -> 0.38472213 | E18: =E123/E131 -> 0.30249783 | F18: =F123/F131 -> 0.22987705 | G18: =G123/G131 -> 0.68780165 | H18: =H123/H131 -> 1.1775845 | I18: =I123/I131 -> 1.0984255 | J18: =J123/J131 -> 0.93941917 | K18: =K123/K131 -> 0.63715229 | ... S18: =S123/S131 -> 1.8464793
B19: 차입금의존도 | D19: =(D105+D114)/D97 -> 0.24740847 | E19: =(E105+E114)/E97 -> 0.20691164 | F19: =(F105+F114)/F97 -> 0.15886186 | G19: =(G105+G114)/G97 -> 0.34656196 | H19: =(H105+H114)/H97 -> 0.4388123 | I19: =(I105+I114)/I97 -> 0.46978628 | J19: =(J105+J114)/J97 -> 0.42319665 | K19: =(K105+K114)/K97 -> 0.35649357 | ... S19: =(S105+S114)/S97 -> 0.58380343
B21: INCOME STATEMENT (억원) | D21: =D$3 -> 2014 | E21: =E$3 -> 2015 | F21: =F$3 -> 2016 | G21: =G$3 -> 2017 | H21: =H$3 -> 2018 | I21: =I$3 -> 2019 | J21: =J$3 -> 2020 | K21: =K$3 -> 2021 | ... S21: =S$3 -> 2027E
B22: 매출액(수익) | C22: A200000.IP | D22: =IFERROR(VLOOKUP($C22,FS_별도!$A:$AL,D$2,FALSE),0) -> 315.19 | E22: =IFERROR(VLOOKUP($C22,FS_별도!$A:$AL,E$2,FALSE),0) -> 216.49 | F22: =IFERROR(VLOOKUP($C22,FS_별도!$A:$AL,F$2,FALSE),0) -> 158.78 | G22: =IFERROR(VLOOKUP($C22,FS_별도!$A:$AL,G$2,FALSE),0) -> 226.43 | H22: =IFERROR(VLOOKUP($C22,FS_별도!$A:$AL,H$2,FALSE),0) -> 471.15 | I22: =IFERROR(VLOOKUP($C22,FS_별도!$A:$AL,I$2,FALSE),0) -> 468.41 | J22: =IFERROR(VLOOKUP($C22,FS_별도!$A:$AL,J$2,FALSE),0) -> 496.3 | K22: =IFERROR(VLOOKUP($C22,FS_별도!$A:$AL,K$2,FALSE),0) -> 472.17 | ... N22: =IFERROR(VLOOKUP($C22,FS_별도!$A:$AL,N$2,FALSE),0) -> 867.23 | O22: =IFERROR(VLOOKUP($C22,'FS_별도(분기누적)'!$A:$BS,O$2,FALSE),0) -> 419.17 | P22: =IFERROR(VLOOKUP($C22,'FS_별도(분기누적)'!$A:$BS,P$2,FALSE),0) -> 500.61
B23: Growth (%) | D23: - | E23: =E22/D22-1 -> -0.31314445 | F23: =F22/E22-1 -> -0.2665712 | G23: =G22/F22-1 -> 0.42606122 | H23: =H22/G22-1 -> 1.0807755 | I23: =I22/H22-1 -> -0.0058155577 | J23: =J22/I22-1 -> 0.059541854 | K23: =K22/J22-1 -> -0.048619786 | L23: =L22/K22-1 -> 0.55973484 | ... N23: =N22/M22-1 -> -0.074875723 | P23: =P22/O22-1 -> 0.19428871 | Q23: =Q22/N22-1 -> -1 | R23: =R22/Q22-1 -> #DIV/0! | S23: =S22/R22-1 -> #DIV/0!
B24: 매출원가 | C24: A200360.IP | D24: =IFERROR(VLOOKUP($C24,FS_별도!$A:$AL,D$2,FALSE),0) -> 267.65 | E24: =IFERROR(VLOOKUP($C24,FS_별도!$A:$AL,E$2,FALSE),0) -> 231.42 | F24: =IFERROR(VLOOKUP($C24,FS_별도!$A:$AL,F$2,FALSE),0) -> 172.73 | G24: =IFERROR(VLOOKUP($C24,FS_별도!$A:$AL,G$2,FALSE),0) -> 183.02 | H24: =IFERROR(VLOOKUP($C24,FS_별도!$A:$AL,H$2,FALSE),0) -> 281.35 | I24: =IFERROR(VLOOKUP($C24,FS_별도!$A:$AL,I$2,FALSE),0) -> 331.72 | J24: =IFERROR(VLOOKUP($C24,FS_별도!$A:$AL,J$2,FALSE),0) -> 396.91 | K24: =IFERROR(VLOOKUP($C24,FS_별도!$A:$AL,K$2,FALSE),0) -> 399.21 | ... N24: =IFERROR(VLOOKUP($C24,FS_별도!$A:$AL,N$2,FALSE),0) -> 1022.3 | O24: =IFERROR(VLOOKUP($C24,'FS_별도(분기누적)'!$A:$BS,O$2,FALSE),0) -> 520.12 | P24: =IFERROR(VLOOKUP($C24,'FS_별도(분기누적)'!$A:$BS,P$2,FALSE),0) -> 489.32 | Q24: =Q22-Q26 -> 0 | R24: =R22-R26 -> 0 | S24: =S22-S26 -> 0
B25: % of sales | D25: =D24/D22 -> 0.84917034 | E25: =E24/E22 -> 1.0689639 | F25: =F24/F22 -> 1.0878574 | G25: =G24/G22 -> 0.80828512 | H25: =H24/H22 -> 0.5971559 | I25: =I24/I22 -> 0.708183 | J25: =J24/J22 -> 0.79973806 | K25: =K24/K22 -> 0.84547938 | ... S25: =S24/S22 -> #DIV/0!
B26: 매출총이익 | D26: =D22-D24 -> 47.54 | E26: =E22-E24 -> -14.93 | F26: =F22-F24 -> -13.95 | G26: =G22-G24 -> 43.41 | H26: =H22-H24 -> 189.8 | I26: =I22-I24 -> 136.69 | J26: =J22-J24 -> 99.39 | K26: =K22-K24 -> 72.96 | ... P26: =P22-P24 -> 11.29 | Q26: =Q32+Q28+Q30 -> 0 | R26: =R32+R28+R30 -> 0 | S26: =S32+S28+S30 -> 0
B27: Gross margin (%) | D27: =D26/D22 -> 0.15082966 | E27: =E26/E22 -> -0.068963924 | F27: =F26/F22 -> -0.087857413 | G27: =G26/G22 -> 0.19171488 | H27: =H26/H22 -> 0.4028441 | I27: =I26/I22 -> 0.291817 | J27: =J26/J22 -> 0.20026194 | K27: =K26/K22 -> 0.15452062 | ... S27: =S26/S22 -> #DIV/0!
B28: 연구개발비 | C28: A201130.IP | D28: =IFERROR(VLOOKUP($C28,FS_별도!$A:$AL,D$2,FALSE),0) -> 0 | E28: =IFERROR(VLOOKUP($C28,FS_별도!$A:$AL,E$2,FALSE),0) -> 0 | F28: =IFERROR(VLOOKUP($C28,FS_별도!$A:$AL,F$2,FALSE),0) -> 0 | G28: =IFERROR(VLOOKUP($C28,FS_별도!$A:$AL,G$2,FALSE),0) -> 0 | H28: =IFERROR(VLOOKUP($C28,FS_별도!$A:$AL,H$2,FALSE),0) -> 0 | I28: =IFERROR(VLOOKUP($C28,FS_별도!$A:$AL,I$2,FALSE),0) -> 0 | J28: =IFERROR(VLOOKUP($C28,FS_별도!$A:$AL,J$2,FALSE),0) -> 0 | K28: =IFERROR(VLOOKUP($C28,FS_별도!$A:$AL,K$2,FALSE),0) -> 0 | ... N28: =IFERROR(VLOOKUP($C28,FS_별도!$A:$AL,N$2,FALSE),0) -> 0 | O28: =IFERROR(VLOOKUP($C28,'FS_별도(분기누적)'!$A:$BS,O$2,FALSE),0) -> 0 | P28: =IFERROR(VLOOKUP($C28,'FS_별도(분기누적)'!$A:$BS,P$2,FALSE),0) -> 0 | Q28: =Q29*Q22 -> 0 | R28: =R29*R22 -> 0 | S28: =S29*S22 -> 0
B29: % of sales | D29: =D28/D22 -> 0 | E29: =E28/E22 -> 0 | F29: =F28/F22 -> 0 | G29: =G28/G22 -> 0 | H29: =H28/H22 -> 0 | I29: =I28/I22 -> 0 | J29: =J28/J22 -> 0 | K29: =K28/K22 -> 0 | ... P29: =P28/P22 -> 0 | Q29: =N29 -> 0 | R29: =Q29 -> 0 | S29: =R29 -> 0
B30: 판매비와관리비(R&D제외) | D30: =D26-D28-D32 -> 24.39 | E30: =E26-E28-E32 -> 26.71 | F30: =F26-F28-F32 -> 20.44 | G30: =G26-G28-G32 -> 23.94 | H30: =H26-H28-H32 -> 29.98 | I30: =I26-I28-I32 -> 55.01 | J30: =J26-J28-J32 -> 33.94 | K30: =K26-K28-K32 -> 32.76 | ... P30: =P26-P28-P32 -> 25.52 | Q30: =Q31*Q22 -> 0 | R30: =R31*R22 -> 0 | S30: =S31*S22 -> 0
B31: % of sales | D31: =D30/D22 -> 0.077381897 | E31: =E30/E22 -> 0.12337752 | F31: =F30/F22 -> 0.12873158 | G31: =G30/G22 -> 0.10572804 | H31: =H30/H22 -> 0.06363154 | I31: =I30/I22 -> 0.11743985 | J31: =J30/J22 -> 0.068386057 | K31: =K30/K22 -> 0.06938179 | ... P31: =P30/P22 -> 0.050977807 | Q31: =N31 -> 0.069485604 | R31: 0.106 | S31: =O31 -> 0.06925591
B32: 영업이익 | C32: A201370.IP | D32: =IFERROR(VLOOKUP($C32,FS_별도!$A:$AL,D$2,FALSE),0) -> 23.15 | E32: =IFERROR(VLOOKUP($C32,FS_별도!$A:$AL,E$2,FALSE),0) -> -41.64 | F32: =IFERROR(VLOOKUP($C32,FS_별도!$A:$AL,F$2,FALSE),0) -> -34.39 | G32: =IFERROR(VLOOKUP($C32,FS_별도!$A:$AL,G$2,FALSE),0) -> 19.47 | H32: =IFERROR(VLOOKUP($C32,FS_별도!$A:$AL,H$2,FALSE),0) -> 159.82 | I32: =IFERROR(VLOOKUP($C32,FS_별도!$A:$AL,I$2,FALSE),0) -> 81.68 | J32: =IFERROR(VLOOKUP($C32,FS_별도!$A:$AL,J$2,FALSE),0) -> 65.45 | K32: =IFERROR(VLOOKUP($C32,FS_별도!$A:$AL,K$2,FALSE),0) -> 40.2 | ... N32: =IFERROR(VLOOKUP($C32,FS_별도!$A:$AL,N$2,FALSE),0) -> -215.33 | O32: =IFERROR(VLOOKUP($C32,'FS_별도(분기누적)'!$A:$BS,O$2,FALSE),0) -> -129.98 | P32: =IFERROR(VLOOKUP($C32,'FS_별도(분기누적)'!$A:$BS,P$2,FALSE),0) -> -14.23
B33: Operating profit margin (%) | D33: =D32/D22 -> 0.073447762 | E33: =E32/E22 -> -0.19234145 | F33: =F32/F22 -> -0.21658899 | G33: =G32/G22 -> 0.085986839 | H33: =H32/H22 -> 0.33921257 | I33: =I32/I22 -> 0.17437715 | J33: =J32/J22 -> 0.13187588 | K33: =K32/K22 -> 0.085138827 | ... P33: =P32/P22 -> -0.028425321
B34: 종속기업,공동지배기업및관계기업관련손익 | C34: A202880.IP | D34: =IFERROR(VLOOKUP($C34,FS_별도!$A:$AL,D$2,FALSE),0) -> 0 | E34: =IFERROR(VLOOKUP($C34,FS_별도!$A:$AL,E$2,FALSE),0) -> 0 | F34: =IFERROR(VLOOKUP($C34,FS_별도!$A:$AL,F$2,FALSE),0) -> 0 | G34: =IFERROR(VLOOKUP($C34,FS_별도!$A:$AL,G$2,FALSE),0) -> 0 | H34: =IFERROR(VLOOKUP($C34,FS_별도!$A:$AL,H$2,FALSE),0) -> 0 | I34: =IFERROR(VLOOKUP($C34,FS_별도!$A:$AL,I$2,FALSE),0) -> 0 | J34: =IFERROR(VLOOKUP($C34,FS_별도!$A:$AL,J$2,FALSE),0) -> 0 | K34: =IFERROR(VLOOKUP($C34,FS_별도!$A:$AL,K$2,FALSE),0) -> 0 | ... N34: =IFERROR(VLOOKUP($C34,FS_별도!$A:$AL,N$2,FALSE),0) -> 0 | O34: =IFERROR(VLOOKUP($C34,'FS_별도(분기누적)'!$A:$BS,O$2,FALSE),0) -> 0 | P34: =IFERROR(VLOOKUP($C34,'FS_별도(분기누적)'!$A:$BS,P$2,FALSE),0) -> 0
B35: 금융수익 | C35: A202210.IP | D35: =IFERROR(VLOOKUP($C35,FS_별도!$A:$AL,D$2,FALSE),0) -> 2.67 | E35: =IFERROR(VLOOKUP($C35,FS_별도!$A:$AL,E$2,FALSE),0) -> 3.24 | F35: =IFERROR(VLOOKUP($C35,FS_별도!$A:$AL,F$2,FALSE),0) -> 2.79 | G35: =IFERROR(VLOOKUP($C35,FS_별도!$A:$AL,G$2,FALSE),0) -> 2.95 | H35: =IFERROR(VLOOKUP($C35,FS_별도!$A:$AL,H$2,FALSE),0) -> 2.84 | I35: =IFERROR(VLOOKUP($C35,FS_별도!$A:$AL,I$2,FALSE),0) -> 8.41 | J35: =IFERROR(VLOOKUP($C35,FS_별도!$A:$AL,J$2,FALSE),0) -> 24.04 | K35: =IFERROR(VLOOKUP($C35,FS_별도!$A:$AL,K$2,FALSE),0) -> 0.89 | ... N35: =IFERROR(VLOOKUP($C35,FS_별도!$A:$AL,N$2,FALSE),0) -> 5.58 | O35: =IFERROR(VLOOKUP($C35,'FS_별도(분기누적)'!$A:$BS,O$2,FALSE),0) -> 3.18 | P35: =IFERROR(VLOOKUP($C35,'FS_별도(분기누적)'!$A:$BS,P$2,FALSE),0) -> 0.84 | Q35: =Q36+Q37+Q38 -> 0 | R35: =R36+R37+R38 -> 0 | S35: =S36+S37+S38 -> 0
B36: 이자수익 | C36: A202220.IP | D36: =IFERROR(VLOOKUP($C36,FS_별도!$A:$AL,D$2,FALSE),0) -> 2.67 | E36: =IFERROR(VLOOKUP($C36,FS_별도!$A:$AL,E$2,FALSE),0) -> 3.24 | F36: =IFERROR(VLOOKUP($C36,FS_별도!$A:$AL,F$2,FALSE),0) -> 2.79 | G36: =IFERROR(VLOOKUP($C36,FS_별도!$A:$AL,G$2,FALSE),0) -> 2.95 | H36: =IFERROR(VLOOKUP($C36,FS_별도!$A:$AL,H$2,FALSE),0) -> 2.84 | I36: =IFERROR(VLOOKUP($C36,FS_별도!$A:$AL,I$2,FALSE),0) -> 2.92 | J36: =IFERROR(VLOOKUP($C36,FS_별도!$A:$AL,J$2,FALSE),0) -> 1.01 | K36: =IFERROR(VLOOKUP($C36,FS_별도!$A:$AL,K$2,FALSE),0) -> 0.89 | ... N36: =IFERROR(VLOOKUP($C36,FS_별도!$A:$AL,N$2,FALSE),0) -> 5.58 | O36: =IFERROR(VLOOKUP($C36,'FS_별도(분기누적)'!$A:$BS,O$2,FALSE),0) -> 0 | P36: =IFERROR(VLOOKUP($C36,'FS_별도(분기누적)'!$A:$BS,P$2,FALSE),0) -> 0 | Q36: =Q226 -> 0 | R36: =R226 -> 0 | S36: =S226 -> 0
B37: 외환거래이익 | C37: A202240.IP | D37: =IFERROR(VLOOKUP($C37,FS_별도!$A:$AL,D$2,FALSE),0) -> 0 | E37: =IFERROR(VLOOKUP($C37,FS_별도!$A:$AL,E$2,FALSE),0) -> 0 | F37: =IFERROR(VLOOKUP($C37,FS_별도!$A:$AL,F$2,FALSE),0) -> 0 | G37: =IFERROR(VLOOKUP($C37,FS_별도!$A:$AL,G$2,FALSE),0) -> 0 | H37: =IFERROR(VLOOKUP($C37,FS_별도!$A:$AL,H$2,FALSE),0) -> 0 | I37: =IFERROR(VLOOKUP($C37,FS_별도!$A:$AL,I$2,FALSE),0) -> 0 | J37: =IFERROR(VLOOKUP($C37,FS_별도!$A:$AL,J$2,FALSE),0) -> 0 | K37: =IFERROR(VLOOKUP($C37,FS_별도!$A:$AL,K$2,FALSE),0) -> 0 | ... N37: =IFERROR(VLOOKUP($C37,FS_별도!$A:$AL,N$2,FALSE),0) -> 0 | O37: =IFERROR(VLOOKUP($C37,'FS_별도(분기누적)'!$A:$BS,O$2,FALSE),0) -> 0 | P37: =IFERROR(VLOOKUP($C37,'FS_별도(분기누적)'!$A:$BS,P$2,FALSE),0) -> 0
B38: 기타금융수익 | D38: =D35-D36-D37 -> 0 | E38: =E35-E36-E37 -> 0 | F38: =F35-F36-F37 -> 0 | G38: =G35-G36-G37 -> 0 | H38: =H35-H36-H37 -> 0 | I38: =I35-I36-I37 -> 5.49 | J38: =J35-J36-J37 -> 23.03 | K38: =K35-K36-K37 -> 0 | ... P38: =P35-P36-P37 -> 0.84 | Q38: 0 | R38: 0 | S38: 0
B39: 금융원가 | C39: A202550.IP | D39: =IFERROR(VLOOKUP($C39,FS_별도!$A:$AL,D$2,FALSE),0) -> 10.53 | E39: =IFERROR(VLOOKUP($C39,FS_별도!$A:$AL,E$2,FALSE),0) -> 5.06 | F39: =IFERROR(VLOOKUP($C39,FS_별도!$A:$AL,F$2,FALSE),0) -> 3.31 | G39: =IFERROR(VLOOKUP($C39,FS_별도!$A:$AL,G$2,FALSE),0) -> 4.67 | H39: =IFERROR(VLOOKUP($C39,FS_별도!$A:$AL,H$2,FALSE),0) -> 15.97 | I39: =IFERROR(VLOOKUP($C39,FS_별도!$A:$AL,I$2,FALSE),0) -> 22.35 | J39: =IFERROR(VLOOKUP($C39,FS_별도!$A:$AL,J$2,FALSE),0) -> 22.49 | K39: =IFERROR(VLOOKUP($C39,FS_별도!$A:$AL,K$2,FALSE),0) -> 30.86 | ... N39: =IFERROR(VLOOKUP($C39,FS_별도!$A:$AL,N$2,FALSE),0) -> 42.59 | O39: =IFERROR(VLOOKUP($C39,'FS_별도(분기누적)'!$A:$BS,O$2,FALSE),0) -> 21.08 | P39: =IFERROR(VLOOKUP($C39,'FS_별도(분기누적)'!$A:$BS,P$2,FALSE),0) -> 19 | Q39: =Q40+Q41+Q42 -> 0 | R39: =R40+R41+R42 -> 0 | S39: =S40+S41+S42 -> 0
B40: 이자비용 | C40: A202560.IP | D40: =IFERROR(VLOOKUP($C40,FS_별도!$A:$AL,D$2,FALSE),0) -> 10.53 | E40: =IFERROR(VLOOKUP($C40,FS_별도!$A:$AL,E$2,FALSE),0) -> 5.06 | F40: =IFERROR(VLOOKUP($C40,FS_별도!$A:$AL,F$2,FALSE),0) -> 3.31 | G40: =IFERROR(VLOOKUP($C40,FS_별도!$A:$AL,G$2,FALSE),0) -> 4.67 | H40: =IFERROR(VLOOKUP($C40,FS_별도!$A:$AL,H$2,FALSE),0) -> 12.09 | I40: =IFERROR(VLOOKUP($C40,FS_별도!$A:$AL,I$2,FALSE),0) -> 22.35 | J40: =IFERROR(VLOOKUP($C40,FS_별도!$A:$AL,J$2,FALSE),0) -> 22.49 | K40: =IFERROR(VLOOKUP($C40,FS_별도!$A:$AL,K$2,FALSE),0) -> 16.44 | ... N40: =IFERROR(VLOOKUP($C40,FS_별도!$A:$AL,N$2,FALSE),0) -> 42.59 | O40: =IFERROR(VLOOKUP($C40,'FS_별도(분기누적)'!$A:$BS,O$2,FALSE),0) -> 0 | P40: =IFERROR(VLOOKUP($C40,'FS_별도(분기누적)'!$A:$BS,P$2,FALSE),0) -> 0 | Q40: =Q232 -> 0 | R40: =R232 -> 0 | S40: =S232 -> 0
B41: 외환거래손실 | C41: A202570.IP | D41: =IFERROR(VLOOKUP($C41,FS_별도!$A:$AL,D$2,FALSE),0) -> 0 | E41: =IFERROR(VLOOKUP($C41,FS_별도!$A:$AL,E$2,FALSE),0) -> 0 | F41: =IFERROR(VLOOKUP($C41,FS_별도!$A:$AL,F$2,FALSE),0) -> 0 | G41: =IFERROR(VLOOKUP($C41,FS_별도!$A:$AL,G$2,FALSE),0) -> 0 | H41: =IFERROR(VLOOKUP($C41,FS_별도!$A:$AL,H$2,FALSE),0) -> 0 | I41: =IFERROR(VLOOKUP($C41,FS_별도!$A:$AL,I$2,FALSE),0) -> 0 | J41: =IFERROR(VLOOKUP($C41,FS_별도!$A:$AL,J$2,FALSE),0) -> 0 | K41: =IFERROR(VLOOKUP($C41,FS_별도!$A:$AL,K$2,FALSE),0) -> 0 | ... N41: =IFERROR(VLOOKUP($C41,FS_별도!$A:$AL,N$2,FALSE),0) -> 0 | O41: =IFERROR(VLOOKUP($C41,'FS_별도(분기누적)'!$A:$BS,O$2,FALSE),0) -> 0 | P41: =IFERROR(VLOOKUP($C41,'FS_별도(분기누적)'!$A:$BS,P$2,FALSE),0) -> 0
...

Sheet Model_연결
B1: =B3&" Financial Statements" -> 연결 Financial Statements
B2: (억원, except per share data) | D2: =Model_별도!D2 -> 18 | E2: =Model_별도!E2 -> 19 | F2: =Model_별도!F2 -> 20 | G2: =Model_별도!G2 -> 21 | H2: =Model_별도!H2 -> 22 | I2: =Model_별도!I2 -> 23 | J2: =Model_별도!J2 -> 24 | K2: =Model_별도!K2 -> 25 | ... P2: =Model_별도!P2 -> 69 | Q2: 지우지마시오 (Vlookup 열순서)
B3: 연결 | C3: 과목코드 | D3: =Model_별도!D3 -> 2014 | E3: =Model_별도!E3 -> 2015 | F3: =Model_별도!F3 -> 2016 | G3: =Model_별도!G3 -> 2017 | H3: =Model_별도!H3 -> 2018 | I3: =Model_별도!I3 -> 2019 | J3: =Model_별도!J3 -> 2020 | K3: =Model_별도!K3 -> 2021 | ... S3: =Model_별도!S3 -> 2027E | W3: 연도 | X3: 매출액 | Y3: 영업이익 | Z3: 순이익 | AA3: 순부채비율
B4: 매출액 | D4: =D22 -> 0 | E4: =E22 -> 0 | F4: =F22 -> 0 | G4: =G22 -> 0 | H4: =H22 -> 0 | I4: =I22 -> 0 | J4: =J22 -> 0 | K4: =K22 -> 0 | ... S4: =S22 -> 0 | W4: '21 | X4: =L4 -> 0 | Y4: =N6 -> 0 | Z4: =N52 -> 0 | AA4: =N14/N131 -> #DIV/0!
B5: 매출성장률 | E5: =E4/D4-1 -> #DIV/0! | F5: =F4/E4-1 -> #DIV/0! | G5: =G4/F4-1 -> #DIV/0! | H5: =H4/G4-1 -> #DIV/0! | I5: =I4/H4-1 -> #DIV/0! | J5: =J4/I4-1 -> #DIV/0! | K5: =K4/J4-1 -> #DIV/0! | L5: =L4/K4-1 -> #DIV/0! | ... N5: =N4/M4-1 -> #DIV/0! | P5: =P4/O4-1 -> #DIV/0! | Q5: =Q4/N4-1 -> #DIV/0! | R5: =R4/Q4-1 -> -1 | S5: =S4/R4-1 -> #DIV/0!
B6: 영업이익 | D6: =D32 -> 0 | E6: =E32 -> 0 | F6: =F32 -> 0 | G6: =G32 -> 0 | H6: =H32 -> 0 | I6: =I32 -> 0 | J6: =J32 -> 0 | K6: =K32 -> 0 | ... S6: =S32 -> 0 | W6: '22 | X6: =M4 -> 0 | Y6: =M6 -> 0 | Z6: =M52 -> 0 | AA6: =M14/M131 -> #DIV/0!
B7: 영업이익률 | D7: =D6/D4 -> #DIV/0! | E7: =E6/E4 -> #DIV/0! | F7: =F6/F4 -> #DIV/0! | G7: =G6/G4 -> #DIV/0! | H7: =H6/H4 -> #DIV/0! | I7: =I6/I4 -> #DIV/0! | J7: =J6/J4 -> #DIV/0! | K7: =K6/K4 -> #DIV/0! | ... S7: =S6/S4 -> #DIV/0!
B8: 당기순이익 | D8: =D52 -> 0 | E8: =E52 -> 0 | F8: =F52 -> 0 | G8: =G52 -> 0 | H8: =H52 -> 0 | I8: =I52 -> 0 | J8: =J52 -> 0 | K8: =K52 -> 0 | ... S8: =S52 -> #DIV/0!
B9: EBITDA | D9: =D250 -> 0 | E9: =E250 -> 0 | F9: =F250 -> 0 | G9: =G250 -> 0 | H9: =H250 -> 0 | I9: =I250 -> 0 | J9: =J250 -> 0 | K9: =K250 -> 0 | ... S9: =S250 -> #DIV/0! | W9: '23 | X9: =N4 -> 0 | Y9: =L6 -> 0 | Z9: =L52 -> 0 | AA9: =L14/L131 -> #DIV/0!
B10: EBITDA/매출액 | D10: =D9/D4 -> #DIV/0! | E10: =E9/E4 -> #DIV/0! | F10: =F9/F4 -> #DIV/0! | G10: =G9/G4 -> #DIV/0! | H10: =H9/H4 -> #DIV/0! | I10: =I9/I4 -> #DIV/0! | J10: =J9/J4 -> #DIV/0! | K10: =K9/K4 -> #DIV/0! | ... S10: =S9/S4 -> #DIV/0!
B11: 자산총계 | D11: =D97 -> 0 | E11: =E97 -> 0 | F11: =F97 -> 0 | G11: =G97 -> 0 | H11: =H97 -> 0 | I11: =I97 -> 0 | J11: =J97 -> 0 | K11: =K97 -> 0 | ... S11: =S97 -> #DIV/0!
B12: 부동산(토지+건물) | D12: =D82+D84+D85 -> 0 | E12: =E82+E84+E85 -> 0 | F12: =F82+F84+F85 -> 0 | G12: =G82+G84+G85 -> 0 | H12: =H82+H84+H85 -> 0 | I12: =I82+I84+I85 -> 0 | J12: =J82+J84+J85 -> 0 | K12: =K82+K84+K85 -> 0 | ... S12: =S82+S84+S85 -> 0
B13: 총차입금 | D13: =D105+D114 -> 0 | E13: =E105+E114 -> 0 | F13: =F105+F114 -> 0 | G13: =G105+G114 -> 0 | H13: =H105+H114 -> 0 | I13: =I105+I114 -> 0 | J13: =J105+J114 -> 0 | K13: =K105+K114 -> 0 | ... S13: =S105+S114 -> 200
B14: 순차입금 | D14: =D105+D114-D62-D63-D90 -> 0 | E14: =E105+E114-E62-E63-E90 -> 0 | F14: =F105+F114-F62-F63-F90 -> 0 | G14: =G105+G114-G62-G63-G90 -> 0 | H14: =H105+H114-H62-H63-H90 -> 0 | I14: =I105+I114-I62-I63-I90 -> 0 | J14: =J105+J114-J62-J63-J90 -> 0 | K14: =K105+K114-K62-K63-K90 -> 0 | ... S14: =S105+S114-S62-S63-S90 -> #DIV/0!
B15: 영업활동CF | D15: =D169 -> 0 | E15: =E169 -> 0 | F15: =F169 -> 0 | G15: =G169 -> 0 | H15: =H169 -> 0 | I15: =I169 -> 0 | J15: =J169 -> 0 | K15: =K169 -> 0 | ... S15: =S169 -> #DIV/0!
B16: 유무형자산투자 | D16: =D170+D171 -> 0 | E16: =E170+E171 -> 0 | F16: =F170+F171 -> 0 | G16: =G170+G171 -> 0 | H16: =H170+H171 -> 0 | I16: =I170+I171 -> 0 | J16: =J170+J171 -> 0 | K16: =K170+K171 -> 0 | ... S16: =S170+S171 -> #DIV/0!
B17: 순차입금/EBITDA | D17: =D14/D9 -> #DIV/0! | E17: =E14/E9 -> #DIV/0! | F17: =F14/F9 -> #DIV/0! | G17: =G14/G9 -> #DIV/0! | H17: =H14/H9 -> #DIV/0! | I17: =I14/I9 -> #DIV/0! | J17: =J14/J9 -> #DIV/0! | K17: =K14/K9 -> #DIV/0! | ... N17: =N14/N9 -> #DIV/0! | O17: =O14/(O9*IF(RIGHT(O$3,2)="1Q",4,IF(RIGHT(O$3,2)="2Q",2,IF(RIGHT(O$3,2)="3Q",4/3,"0")))) -> #DIV/0! | P17: =P14/(P9*IF(RIGHT(P$3,2)="1Q",4,IF(RIGHT(P$3,2)="2Q",2,IF(RIGHT(P$3,2)="3Q",4/3,"0")))) -> #DIV/0! | Q17: =Q14/Q9 -> #DIV/0! | R17: =R14/R9 -> #DIV/0! | S17: =S14/S9 -> #DIV/0!
B18: 부채비율 | D18: =D123/D131 -> #DIV/0! | E18: =E123/E131 -> #DIV/0! | F18: =F123/F131 -> #DIV/0! | G18: =G123/G131 -> #DIV/0! | H18: =H123/H131 -> #DIV/0! | I18: =I123/I131 -> #DIV/0! | J18: =J123/J131 -> #DIV/0! | K18: =K123/K131 -> #DIV/0! | ... S18: =S123/S131 -> #DIV/0!
B19: 차입금의존도 | D19: =(D105+D114)/D97 -> #DIV/0! | E19: =(E105+E114)/E97 -> #DIV/0! | F19: =(F105+F114)/F97 -> #DIV/0! | G19: =(G105+G114)/G97 -> #DIV/0! | H19: =(H105+H114)/H97 -> #DIV/0! | I19: =(I105+I114)/I97 -> #DIV/0! | J19: =(J105+J114)/J97 -> #DIV/0! | K19: =(K105+K114)/K97 -> #DIV/0! | ... S19: =(S105+S114)/S97 -> #DIV/0!
B21: INCOME STATEMENT (억원) | D21: =D$3 -> 2014 | E21: =E$3 -> 2015 | F21: =F$3 -> 2016 | G21: =G$3 -> 2017 | H21: =H$3 -> 2018 | I21: =I$3 -> 2019 | J21: =J$3 -> 2020 | K21: =K$3 -> 2021 | ... S21: =S$3 -> 2027E
B22: 매출액(수익) | C22: A200000.IC | D22: =IFERROR(VLOOKUP($C22,FS_연결!$A:$Z,D$2,FALSE),0) -> 0 | E22: =IFERROR(VLOOKUP($C22,FS_연결!$A:$Z,E$2,FALSE),0) -> 0 | F22: =IFERROR(VLOOKUP($C22,FS_연결!$A:$Z,F$2,FALSE),0) -> 0 | G22: =IFERROR(VLOOKUP($C22,FS_연결!$A:$Z,G$2,FALSE),0) -> 0 | H22: =IFERROR(VLOOKUP($C22,FS_연결!$A:$Z,H$2,FALSE),0) -> 0 | I22: =IFERROR(VLOOKUP($C22,FS_연결!$A:$Z,I$2,FALSE),0) -> 0 | J22: =IFERROR(VLOOKUP($C22,FS_연결!$A:$Z,J$2,FALSE),0) -> 0 | K22: =IFERROR(VLOOKUP($C22,FS_연결!$A:$Z,K$2,FALSE),0) -> 0 | L22: =IFERROR(VLOOKUP($C22,FS_연결!$A:$Z,L$2,FALSE),0) -> 0 | M22: =IFERROR(VLOOKUP($C22,FS_연결!$A:$AL,M$2,FALSE),0) -> 0 | N22: =IFERROR(VLOOKUP($C22,FS_연결!$A:$AL,N$2,FALSE),0) -> 0 | O22: =IFERROR(VLOOKUP($C22,'FS_연결(분기누적)'!$A:$BS,O$2,FALSE),0) -> 0 | P22: =IFERROR(VLOOKUP($C22,'FS_연결(분기누적)'!$A:$BS,P$2,FALSE),0) -> 0 | Q22: =컨센!F15/100000 -> 1051 | R22: =컨센!G15/100000 -> 0 | S22: =컨센!H15/100000 -> 0
B23: Growth (%) | D23: - | E23: =E22/D22-1 -> #DIV/0! | F23: =F22/E22-1 -> #DIV/0! | G23: =G22/F22-1 -> #DIV/0! | H23: =H22/G22-1 -> #DIV/0! | I23: =I22/H22-1 -> #DIV/0! | J23: =J22/I22-1 -> #DIV/0! | K23: =K22/J22-1 -> #DIV/0! | L23: =L22/K22-1 -> #DIV/0! | ... N23: =N22/M22-1 -> #DIV/0! | P23: =P22/O22-1 -> #DIV/0! | Q23: =Q22/N22-1 -> #DIV/0! | R23: =R22/Q22-1 -> -1 | S23: =S22/R22-1 -> #DIV/0!
B24: 매출원가 | C24: A200360.IC | D24: =IFERROR(VLOOKUP($C24,FS_연결!$A:$Z,D$2,FALSE),0) -> 0 | E24: =IFERROR(VLOOKUP($C24,FS_연결!$A:$Z,E$2,FALSE),0) -> 0 | F24: =IFERROR(VLOOKUP($C24,FS_연결!$A:$Z,F$2,FALSE),0) -> 0 | G24: =IFERROR(VLOOKUP($C24,FS_연결!$A:$Z,G$2,FALSE),0) -> 0 | H24: =IFERROR(VLOOKUP($C24,FS_연결!$A:$Z,H$2,FALSE),0) -> 0 | I24: =IFERROR(VLOOKUP($C24,FS_연결!$A:$Z,I$2,FALSE),0) -> 0 | J24: =IFERROR(VLOOKUP($C24,FS_연결!$A:$Z,J$2,FALSE),0) -> 0 | K24: =IFERROR(VLOOKUP($C24,FS_연결!$A:$Z,K$2,FALSE),0) -> 0 | L24: =IFERROR(VLOOKUP($C24,FS_연결!$A:$Z,L$2,FALSE),0) -> 0 | M24: =IFERROR(VLOOKUP($C24,FS_연결!$A:$AL,M$2,FALSE),0) -> 0 | N24: =IFERROR(VLOOKUP($C24,FS_연결!$A:$AL,N$2,FALSE),0) -> 0 | O24: =IFERROR(VLOOKUP($C24,'FS_연결(분기누적)'!$A:$BS,O$2,FALSE),0) -> 0 | P24: =IFERROR(VLOOKUP($C24,'FS_연결(분기누적)'!$A:$BS,P$2,FALSE),0) -> 0 | Q24: =Q22*Q25 -> #DIV/0! | R24: =R22*R25 -> #DIV/0! | S24: =S22*S25 -> #DIV/0!
B25: % of sales | D25: =D24/D22 -> #DIV/0! | E25: =E24/E22 -> #DIV/0! | F25: =F24/F22 -> #DIV/0! | G25: =G24/G22 -> #DIV/0! | H25: =H24/H22 -> #DIV/0! | I25: =I24/I22 -> #DIV/0! | J25: =J24/J22 -> #DIV/0! | K25: =K24/K22 -> #DIV/0! | ... P25: =P24/P22 -> #DIV/0! | Q25: =N25 -> #DIV/0! | R25: =Q25-0.002 -> #DIV/0! | S25: =R25-0.002 -> #DIV/0!
B26: 매출총이익 | D26: =D22-D24 -> 0 | E26: =E22-E24 -> 0 | F26: =F22-F24 -> 0 | G26: =G22-G24 -> 0 | H26: =H22-H24 -> 0 | I26: =I22-I24 -> 0 | J26: =J22-J24 -> 0 | K26: =K22-K24 -> 0 | ... S26: =S22-S24 -> #DIV/0!
B27: Gross margin (%) | D27: =D26/D22 -> #DIV/0! | E27: =E26/E22 -> #DIV/0! | F27: =F26/F22 -> #DIV/0! | G27: =G26/G22 -> #DIV/0! | H27: =H26/H22 -> #DIV/0! | I27: =I26/I22 -> #DIV/0! | J27: =J26/J22 -> #DIV/0! | K27: =K26/K22 -> #DIV/0! | ... S27: =S26/S22 -> #DIV/0!
B28: 연구개발비 | C28: A201130.IC | D28: =IFERROR(VLOOKUP($C28,FS_연결!$A:$Z,D$2,FALSE),0) -> 0 | E28: =IFERROR(VLOOKUP($C28,FS_연결!$A:$Z,E$2,FALSE),0) -> 0 | F28: =IFERROR(VLOOKUP($C28,FS_연결!$A:$Z,F$2,FALSE),0) -> 0 | G28: =IFERROR(VLOOKUP($C28,FS_연결!$A:$Z,G$2,FALSE),0) -> 0 | H28: =IFERROR(VLOOKUP($C28,FS_연결!$A:$Z,H$2,FALSE),0) -> 0 | I28: =IFERROR(VLOOKUP($C28,FS_연결!$A:$Z,I$2,FALSE),0) -> 0 | J28: =IFERROR(VLOOKUP($C28,FS_연결!$A:$Z,J$2,FALSE),0) -> 0 | K28: =IFERROR(VLOOKUP($C28,FS_연결!$A:$Z,K$2,FALSE),0) -> 0 | L28: =IFERROR(VLOOKUP($C28,FS_연결!$A:$Z,L$2,FALSE),0) -> 0 | M28: =IFERROR(VLOOKUP($C28,FS_연결!$A:$AL,M$2,FALSE),0) -> 0 | N28: =IFERROR(VLOOKUP($C28,FS_연결!$A:$AL,N$2,FALSE),0) -> 0 | O28: =IFERROR(VLOOKUP($C28,'FS_연결(분기누적)'!$A:$BS,O$2,FALSE),0) -> 0 | P28: =IFERROR(VLOOKUP($C28,'FS_연결(분기누적)'!$A:$BS,P$2,FALSE),0) -> 0 | Q28: =Q29*Q$22 -> #DIV/0! | R28: =R29*R$22 -> #DIV/0! | S28: =S29*S$22 -> #DIV/0!
B29: % of sales | D29: =D28/D22 -> #DIV/0! | E29: =E28/E22 -> #DIV/0! | F29: =F28/F22 -> #DIV/0! | G29: =G28/G22 -> #DIV/0! | H29: =H28/H22 -> #DIV/0! | I29: =I28/I22 -> #DIV/0! | J29: =J28/J22 -> #DIV/0! | K29: =K28/K22 -> #DIV/0! | ... P29: =P28/P22 -> #DIV/0! | Q29: =P29 -> #DIV/0! | R29: =N29 -> #DIV/0! | S29: =L29 -> #DIV/0!
B30: 판매비와관리비(R&D제외) | D30: =D26-D28-D32 -> 0 | E30: =E26-E28-E32 -> 0 | F30: =F26-F28-F32 -> 0 | G30: =G26-G28-G32 -> 0 | H30: =H26-H28-H32 -> 0 | I30: =I26-I28-I32 -> 0 | J30: =J26-J28-J32 -> 0 | K30: =K26-K28-K32 -> 0 | ... S30: =S26-S28-S32 -> #DIV/0!
B31: % of sales | D31: =D30/D22 -> #DIV/0! | E31: =E30/E22 -> #DIV/0! | F31: =F30/F22 -> #DIV/0! | G31: =G30/G22 -> #DIV/0! | H31: =H30/H22 -> #DIV/0! | I31: =I30/I22 -> #DIV/0! | J31: =J30/J22 -> #DIV/0! | K31: =K30/K22 -> #DIV/0! | ... S31: =S30/S22 -> #DIV/0!
B32: 영업이익 | C32: A201370.IC | D32: =IFERROR(VLOOKUP($C32,FS_연결!$A:$Z,D$2,FALSE),0) -> 0 | E32: =IFERROR(VLOOKUP($C32,FS_연결!$A:$Z,E$2,FALSE),0) -> 0 | F32: =IFERROR(VLOOKUP($C32,FS_연결!$A:$Z,F$2,FALSE),0) -> 0 | G32: =IFERROR(VLOOKUP($C32,FS_연결!$A:$Z,G$2,FALSE),0) -> 0 | H32: =IFERROR(VLOOKUP($C32,FS_연결!$A:$Z,H$2,FALSE),0) -> 0 | I32: =IFERROR(VLOOKUP($C32,FS_연결!$A:$Z,I$2,FALSE),0) -> 0 | J32: =IFERROR(VLOOKUP($C32,FS_연결!$A:$Z,J$2,FALSE),0) -> 0 | K32: =IFERROR(VLOOKUP($C32,FS_연결!$A:$Z,K$2,FALSE),0) -> 0 | L32: =IFERROR(VLOOKUP($C32,FS_연결!$A:$Z,L$2,FALSE),0) -> 0 | M32: =IFERROR(VLOOKUP($C32,FS_연결!$A:$AL,M$2,FALSE),0) -> 0 | N32: =IFERROR(VLOOKUP($C32,FS_연결!$A:$AL,N$2,FALSE),0) -> 0 | O32: =IFERROR(VLOOKUP($C32,'FS_연결(분기누적)'!$A:$BS,O$2,FALSE),0) -> 0 | P32: =IFERROR(VLOOKUP($C32,'FS_연결(분기누적)'!$A:$BS,P$2,FALSE),0) -> 0 | Q32: =컨센!K15/100000 -> 12 | R32: =컨센!L15/100000 -> 0 | S32: =컨센!M15/100000 -> 0
B33: Operating profit margin (%) | D33: =D32/D22 -> #DIV/0! | E33: =E32/E22 -> #DIV/0! | F33: =F32/F22 -> #DIV/0! | G33: =G32/G22 -> #DIV/0! | H33: =H32/H22 -> #DIV/0! | I33: =I32/I22 -> #DIV/0! | J33: =J32/J22 -> #DIV/0! | K33: =K32/K22 -> #DIV/0! | ... S33: =S32/S22 -> #DIV/0!
B34: 종속기업,공동지배기업및관계기업관련손익 | C34: A202880.IC | D34: =IFERROR(VLOOKUP($C34,FS_연결!$A:$Z,D$2,FALSE),0) -> 0 | E34: =IFERROR(VLOOKUP($C34,FS_연결!$A:$Z,E$2,FALSE),0) -> 0 | F34: =IFERROR(VLOOKUP($C34,FS_연결!$A:$Z,F$2,FALSE),0) -> 0 | G34: =IFERROR(VLOOKUP($C34,FS_연결!$A:$Z,G$2,FALSE),0) -> 0 | H34: =IFERROR(VLOOKUP($C34,FS_연결!$A:$Z,H$2,FALSE),0) -> 0 | I34: =IFERROR(VLOOKUP($C34,FS_연결!$A:$Z,I$2,FALSE),0) -> 0 | J34: =IFERROR(VLOOKUP($C34,FS_연결!$A:$Z,J$2,FALSE),0) -> 0 | K34: =IFERROR(VLOOKUP($C34,FS_연결!$A:$Z,K$2,FALSE),0) -> 0 | L34: =IFERROR(VLOOKUP($C34,FS_연결!$A:$Z,L$2,FALSE),0) -> 0 | M34: =IFERROR(VLOOKUP($C34,FS_연결!$A:$AL,M$2,FALSE),0) -> 0 | N34: =IFERROR(VLOOKUP($C34,FS_연결!$A:$AL,N$2,FALSE),0) -> 0 | O34: =IFERROR(VLOOKUP($C34,'FS_연결(분기누적)'!$A:$BS,O$2,FALSE),0) -> 0 | P34: =IFERROR(VLOOKUP($C34,'FS_연결(분기누적)'!$A:$BS,P$2,FALSE),0) -> 0
B35: 금융수익 | C35: A202210.IC | D35: =IFERROR(VLOOKUP($C35,FS_연결!$A:$Z,D$2,FALSE),0) -> 0 | E35: =IFERROR(VLOOKUP($C35,FS_연결!$A:$Z,E$2,FALSE),0) -> 0 | F35: =IFERROR(VLOOKUP($C35,FS_연결!$A:$Z,F$2,FALSE),0) -> 0 | G35: =IFERROR(VLOOKUP($C35,FS_연결!$A:$Z,G$2,FALSE),0) -> 0 | H35: =IFERROR(VLOOKUP($C35,FS_연결!$A:$Z,H$2,FALSE),0) -> 0 | I35: =IFERROR(VLOOKUP($C35,FS_연결!$A:$Z,I$2,FALSE),0) -> 0 | J35: =IFERROR(VLOOKUP($C35,FS_연결!$A:$Z,J$2,FALSE),0) -> 0 | K35: =IFERROR(VLOOKUP($C35,FS_연결!$A:$Z,K$2,FALSE),0) -> 0 | L35: =IFERROR(VLOOKUP($C35,FS_연결!$A:$Z,L$2,FALSE),0) -> 0 | M35: =IFERROR(VLOOKUP($C35,FS_연결!$A:$AL,M$2,FALSE),0) -> 0 | N35: =IFERROR(VLOOKUP($C35,FS_연결!$A:$AL,N$2,FALSE),0) -> 0 | O35: =IFERROR(VLOOKUP($C35,'FS_연결(분기누적)'!$A:$BS,O$2,FALSE),0) -> 0 | P35: =IFERROR(VLOOKUP($C35,'FS_연결(분기누적)'!$A:$BS,P$2,FALSE),0) -> 0 | Q35: =Q36+Q37+Q38 -> 0 | R35: =R36+R37+R38 -> #DIV/0! | S35: =S36+S37+S38 -> #DIV/0!
B36: 이자수익 | C36: A202220.IC | D36: =IFERROR(VLOOKUP($C36,FS_연결!$A:$Z,D$2,FALSE),0) -> 0 | E36: =IFERROR(VLOOKUP($C36,FS_연결!$A:$Z,E$2,FALSE),0) -> 0 | F36: =IFERROR(VLOOKUP($C36,FS_연결!$A:$Z,F$2,FALSE),0) -> 0 | G36: =IFERROR(VLOOKUP($C36,FS_연결!$A:$Z,G$2,FALSE),0) -> 0 | H36: =IFERROR(VLOOKUP($C36,FS_연결!$A:$Z,H$2,FALSE),0) -> 0 | I36: =IFERROR(VLOOKUP($C36,FS_연결!$A:$Z,I$2,FALSE),0) -> 0 | J36: =IFERROR(VLOOKUP($C36,FS_연결!$A:$Z,J$2,FALSE),0) -> 0 | K36: =IFERROR(VLOOKUP($C36,FS_연결!$A:$Z,K$2,FALSE),0) -> 0 | L36: =IFERROR(VLOOKUP($C36,FS_연결!$A:$Z,L$2,FALSE),0) -> 0 | M36: =IFERROR(VLOOKUP($C36,FS_연결!$A:$AL,M$2,FALSE),0) -> 0 | N36: =IFERROR(VLOOKUP($C36,FS_연결!$A:$AL,N$2,FALSE),0) -> 0 | O36: =IFERROR(VLOOKUP($C36,'FS_연결(분기누적)'!$A:$BS,O$2,FALSE),0) -> 0 | P36: =IFERROR(VLOOKUP($C36,'FS_연결(분기누적)'!$A:$BS,P$2,FALSE),0) -> 0 | Q36: =Q226 -> 0 | R36: =R226 -> #DIV/0! | S36: =S226 -> #DIV/0! | W36: 구분 | X36: 23E | Y36: 24E | Z36: 25E
B37: 외환거래이익 | C37: A202240.IC | D37: =IFERROR(VLOOKUP($C37,FS_연결!$A:$Z,D$2,FALSE),0) -> 0 | E37: =IFERROR(VLOOKUP($C37,FS_연결!$A:$Z,E$2,FALSE),0) -> 0 | F37: =IFERROR(VLOOKUP($C37,FS_연결!$A:$Z,F$2,FALSE),0) -> 0 | G37: =IFERROR(VLOOKUP($C37,FS_연결!$A:$Z,G$2,FALSE),0) -> 0 | H37: =IFERROR(VLOOKUP($C37,FS_연결!$A:$Z,H$2,FALSE),0) -> 0 | I37: =IFERROR(VLOOKUP($C37,FS_연결!$A:$Z,I$2,FALSE),0) -> 0 | J37: =IFERROR(VLOOKUP($C37,FS_연결!$A:$Z,J$2,FALSE),0) -> 0 | K37: =IFERROR(VLOOKUP($C37,FS_연결!$A:$Z,K$2,FALSE),0) -> 0 | L37: =IFERROR(VLOOKUP($C37,FS_연결!$A:$Z,L$2,FALSE),0) -> 0 | M37: =IFERROR(VLOOKUP($C37,FS_연결!$A:$AL,M$2,FALSE),0) -> 0 | N37: =IFERROR(VLOOKUP($C37,FS_연결!$A:$AL,N$2,FALSE),0) -> 0 | O37: =IFERROR(VLOOKUP($C37,'FS_연결(분기누적)'!$A:$BS,O$2,FALSE),0) -> 0 | P37: =IFERROR(VLOOKUP($C37,'FS_연결(분기누적)'!$A:$BS,P$2,FALSE),0) -> 0 | W37: 시가총액 | X37: =Valuation!C27 -> 0
B38: 기타금융수익 | D38: =D35-D36-D37 -> 0 | E38: =E35-E36-E37 -> 0 | F38: =F35-F36-F37 -> 0 | G38: =G35-G36-G37 -> 0 | H38: =H35-H36-H37 -> 0 | I38: =I35-I36-I37 -> 0 | J38: =J35-J36-J37 -> 0 | K38: =K35-K36-K37 -> 0 | ... P38: =P35-P36-P37 -> 0 | Q38: 0 | R38: 0 | S38: 0 | W38: NI | X38: =Q44 -> #DIV/0! | Y38: =R44 -> #DIV/0! | Z38: =S44 -> #DIV/0!
